Workbook

Sheet 计算口径
A1: 项目 | B1: 当前口径
A2: 初始资金 | B2: 20000
A3: 简单难度 | B3: 李言闻1000文/节气；每天2次妙手回春
A4: 普通难度 | B4: 李言闻500文/节气；每天3次妙手回春
A5: 困难难度 | B5: 李言闻0文/节气；每天4次妙手回春
A6: 第一年立春 | B6: 剧情跳过，无普通随机NPC诊疗
A7: 妙手回春 | B7: 每人名望+10、心得+1
A8: 药材净收入预期 | B8: 按每名随机病人生成时的已解锁疾病/方剂池动态计算；不再固定使用106.90625文/次
A9: 病家谢仪期望 | B9: 115.2
A10: 田租 | B10: 大暑+5000文；霜降+15000文
A11: 李建中俸禄 | B11: 按用户要求不触发
A12: 004_02 老师 | B12: 银钱0、名望0、心得0
A13: 005_02 世子 | B13: 银钱+1000、名望+1000、心得0；night_end结算
A14: 谢飞燕两次治疗 | B14: 023_02 +1000文；024_02 +1000文；合计+2000文
A15: 024_04 王百堂 | B15: 心得+7，影响后续条目/剧情解锁时间
A16: 方剂解锁假设 | B16: 药材条目达到心得阈值后及时阅读；药材齐全即解锁方剂及对应疾病
A17: 同节气内动态更新 | B17: 每次妙手回春+1心得，下一名random NPC立即按新解锁池计算期望药材收益
A18: 022_02 敬亭 | B18: 银钱+1000；按本次用户要求加入（当前项目数据中的人物名为柳敬亭）

Sheet 剧情奖励核对
A1: 剧情ID | B1: 剧情 | C1: 银钱 | D1: 名望 | E1: 心得 | F1: GitHub current main | G1: 说明
A2: 005_02 | B2: 治愈世子 | C2: 1000 | D2: 1000 | E2: 0 | F2: https://github.com/lqc19891229/Doctor/blob/main/Data/Story/005_02.tres | G2: night_end；+1000名望从下一节气普通诊费开始产生完整影响
A3: 014_02 | B3: 沈修文治疗成功 | C3: 1000 | D3: 0 | E3: 0 | F3: https://github.com/lqc19891229/Doctor/blob/main/Data/Story/014_02.tres | G3: 前置剧情链满足且心脾两虚已解锁后触发
A4: 017_02 | B4: 杨善泉治疗成功 | C4: 1000 | D4: 0 | E4: 0 | F4: https://github.com/lqc19891229/Doctor/blob/main/Data/Story/017_02.tres | G4: 前置剧情链满足且肾气不固已解锁后触发
A5: 022_02 | B5: 敬亭治疗成功 | C5: 1000 | D5: 0 | E5: 0 | F5: 用户本次指定（待同步项目数据） | G5: 用户要求加入+1000文；当前项目数据人物为柳敬亭（liu_jing_ting）
A6: 023_02 | B6: 谢飞燕肺气虚治疗成功 | C6: 1000 | D6: 0 | E6: 0 | F6: https://github.com/lqc19891229/Doctor/blob/main/Data/Story/023_02.tres | G6: 谢飞燕第一笔1000文
A7: 024_02 | B7: 谢飞燕肺阴虚治疗成功 | C7: 1000 | D7: 0 | E7: 0 | F7: https://github.com/lqc19891229/Doctor/blob/main/Data/Story/024_02.tres | G7: 谢飞燕第二笔1000文
A8: 024_04 | B8: 王百堂来访 | C8: 0 | D8: 0 | E8: 7 | F8: https://github.com/lqc19891229/Doctor/blob/main/Data/Story/024_04.tres | G8: 无银钱，但+7心得会提前后续条目/剧情
A9: 025_02 | B9: 和尚肾精不足治疗成功 | C9: 2000 | D9: 0 | E9: 0 | F9: https://github.com/lqc19891229/Doctor/blob/main/Data/Story/025_02.tres | G9: 前两年内部分难度可触发

Sheet 简单
A1: 年份 | B1: 节气 | C1: 妙手回春次数 | D1: 李言闻收入 | E1: 诊费预期 | F1: 药材净收入预期 | G1: 谢仪预期 | H1: 田租 | I1: 剧情银钱奖励 | J1: 预期收入 | K1: 累计预期收入 | L1: 预期支出 | M1: 累计预期支出 | N1: 本节气收支差 | O1: 累计收支差 | P1: 含初始资金余额 | Q1: 节气末名望 | R1: 节气末心得 | S1: 剧情备注
A2: 1 | B2: 立春 | C2: 0 | D2: 0 | E2: 0 | F2: =IF(C2>=1,VLOOKUP(0+MAX(0,R2-0-C2)+0,药材收益口径!$H$2:$I$222,2,FALSE),0)+IF(C2>=2,VLOOKUP(0+MAX(0,R2-0-C2)+1,药材收益口径!$H$2:$I$222,2,FALSE),0)+IF(C2>=3,VLOOKUP(0+MAX(0,R2-0-C2)+2,药材收益口径!$H$2:$I$222,2,FALSE),0)+IF(C2>=4,VLOOKUP(0+MAX(0,R2-0-C2)+3,药材收益口径!$H$2:$I$222,2,FALSE),0) -> 0 | G2: 0 | H2: 0 | I2: 0 | J2: =SUM(D2:I2) -> 0 | K2: =J2 -> 0 | L2: =K2 -> 0 | M2: =L2 -> 0 | N2: =J2-L2 -> 0 | O2: =K2-M2 -> 0 | P2: =20000+O2 -> 20000 | Q2: 0 | R2: 0
A3: 1 | B3: 雨水 | C3: 2 | D3: 1000 | E3: 40 | F3: =IF(C3>=1,VLOOKUP(R2+MAX(0,R3-R2-C3)+0,药材收益口径!$H$2:$I$222,2,FALSE),0)+IF(C3>=2,VLOOKUP(R2+MAX(0,R3-R2-C3)+1,药材收益口径!$H$2:$I$222,2,FALSE),0)+IF(C3>=3,VLOOKUP(R2+MAX(0,R3-R2-C3)+2,药材收益口径!$H$2:$I$222,2,FALSE),0)+IF(C3>=4,VLOOKUP(R2+MAX(0,R3-R2-C3)+3,药材收益口径!$H$2:$I$222,2,FALSE),0) -> 39.333333 | G3: 230.4 | H3: 0 | I3: 0 | J3: =SUM(D3:I3) -> 1309.7333 | K3: =K2+J3 -> 1309.7333 | L3: 2776.4 | M3: =M2+L3 -> 2776.4 | N3: =J3-L3 -> -1466.6667 | O3: =K3-M3 -> -1466.6667 | P3: =20000+O3 -> 18533.333 | Q3: 20 | R3: 2
A4: 1 | B4: 惊蛰 | C4: 2 | D4: 1000 | E4: 40 | F4: =IF(C4>=1,VLOOKUP(R3+MAX(0,R4-R3-C4)+0,药材收益口径!$H$2:$I$222,2,FALSE),0)+IF(C4>=2,VLOOKUP(R3+MAX(0,R4-R3-C4)+1,药材收益口径!$H$2:$I$222,2,FALSE),0)+IF(C4>=3,VLOOKUP(R3+MAX(0,R4-R3-C4)+2,药材收益口径!$H$2:$I$222,2,FALSE),0)+IF(C4>=4,VLOOKUP(R3+MAX(0,R4-R3-C4)+3,药材收益口径!$H$2:$I$222,2,FALSE),0) -> 39.333333 | G4: 230.4 | H4: 0 | I4: 0 | J4: =SUM(D4:I4) -> 1309.7333 | K4: =K3+J4 -> 2619.4667 | L4: 1550 | M4: =M3+L4 -> 4326.4 | N4: =J4-L4 -> -240.26667 | O4: =K4-M4 -> -1706.9333 | P4: =20000+O4 -> 18293.067 | Q4: 40 | R4: 4
A5: 1 | B5: 春分 | C5: 2 | D5: 1000 | E5: 40 | F5: =IF(C5>=1,VLOOKUP(R4+MAX(0,R5-R4-C5)+0,药材收益口径!$H$2:$I$222,2,FALSE),0)+IF(C5>=2,VLOOKUP(R4+MAX(0,R5-R4-C5)+1,药材收益口径!$H$2:$I$222,2,FALSE),0)+IF(C5>=3,VLOOKUP(R4+MAX(0,R5-R4-C5)+2,药材收益口径!$H$2:$I$222,2,FALSE),0)+IF(C5>=4,VLOOKUP(R4+MAX(0,R5-R4-C5)+3,药材收益口径!$H$2:$I$222,2,FALSE),0) -> 39.333333 | G5: 230.4 | H5: 0 | I5: 0 | J5: =SUM(D5:I5) -> 1309.7333 | K5: =K4+J5 -> 3929.2 | L5: 3376.4 | M5: =M4+L5 -> 7702.8 | N5: =J5-L5 -> -2066.6667 | O5: =K5-M5 -> -3773.6 | P5: =20000+O5 -> 16226.4 | Q5: 60 | R5: 6
A6: 1 | B6: 清明 | C6: 2 | D6: 1000 | E6: 40 | F6: =IF(C6>=1,VLOOKUP(R5+MAX(0,R6-R5-C6)+0,药材收益口径!$H$2:$I$222,2,FALSE),0)+IF(C6>=2,VLOOKUP(R5+MAX(0,R6-R5-C6)+1,药材收益口径!$H$2:$I$222,2,FALSE),0)+IF(C6>=3,VLOOKUP(R5+MAX(0,R6-R5-C6)+2,药材收益口径!$H$2:$I$222,2,FALSE),0)+IF(C6>=4,VLOOKUP(R5+MAX(0,R6-R5-C6)+3,药材收益口径!$H$2:$I$222,2,FALSE),0) -> 39.333333 | G6: 230.4 | H6: 0 | I6: 0 | J6: =SUM(D6:I6) -> 1309.7333 | K6: =K5+J6 -> 5238.9333 | L6: 3550 | M6: =M5+L6 -> 11252.8 | N6: =J6-L6 -> -2240.2667 | O6: =K6-M6 -> -6013.8667 | P6: =20000+O6 -> 13986.133 | Q6: 80 | R6: 8
A7: 1 | B7: 谷雨 | C7: 2 | D7: 1000 | E7: 40 | F7: =IF(C7>=1,VLOOKUP(R6+MAX(0,R7-R6-C7)+0,药材收益口径!$H$2:$I$222,2,FALSE),0)+IF(C7>=2,VLOOKUP(R6+MAX(0,R7-R6-C7)+1,药材收益口径!$H$2:$I$222,2,FALSE),0)+IF(C7>=3,VLOOKUP(R6+MAX(0,R7-R6-C7)+2,药材收益口径!$H$2:$I$222,2,FALSE),0)+IF(C7>=4,VLOOKUP(R6+MAX(0,R7-R6-C7)+3,药材收益口径!$H$2:$I$222,2,FALSE),0) -> 88.916667 | G7: 230.4 | H7: 0 | I7: 0 | J7: =SUM(D7:I7) -> 1359.3167 | K7: =K6+J7 -> 6598.25 | L7: 2776.4 | M7: =M6+L7 -> 14029.2 | N7: =J7-L7 -> -1417.0833 | O7: =K7-M7 -> -7430.95 | P7: =20000+O7 -> 12569.05 | Q7: 100 | R7: 10
A8: 1 | B8: 立夏 | C8: 2 | D8: 1000 | E8: 70 | F8: =IF(C8>=1,VLOOKUP(R7+MAX(0,R8-R7-C8)+0,药材收益口径!$H$2:$I$222,2,FALSE),0)+IF(C8>=2,VLOOKUP(R7+MAX(0,R8-R7-C8)+1,药材收益口径!$H$2:$I$222,2,FALSE),0)+IF(C8>=3,VLOOKUP(R7+MAX(0,R8-R7-C8)+2,药材收益口径!$H$2:$I$222,2,FALSE),0)+IF(C8>=4,VLOOKUP(R7+MAX(0,R8-R7-C8)+3,药材收益口径!$H$2:$I$222,2,FALSE),0) -> 138.5 | G8: 230.4 | H8: 0 | I8: 0 | J8: =SUM(D8:I8) -> 1438.9 | K8: =K7+J8 -> 8037.15 | L8: 2650 | M8: =M7+L8 -> 16679.2 | N8: =J8-L8 -> -1211.1 | O8: =K8-M8 -> -8642.05 | P8: =20000+O8 -> 11357.95 | Q8: 120 | R8: 12
A9: 1 | B9: 小满 | C9: 2 | D9: 1000 | E9: 100 | F9: =IF(C9>=1,VLOOKUP(R8+MAX(0,R9-R8-C9)+0,药材收益口径!$H$2:$I$222,2,FALSE),0)+IF(C9>=2,VLOOKUP(R8+MAX(0,R9-R8-C9)+1,药材收益口径!$H$2:$I$222,2,FALSE),0)+IF(C9>=3,VLOOKUP(R8+MAX(0,R9-R8-C9)+2,药材收益口径!$H$2:$I$222,2,FALSE),0)+IF(C9>=4,VLOOKUP(R8+MAX(0,R9-R8-C9)+3,药材收益口径!$H$2:$I$222,2,FALSE),0) -> 138.5 | G9: 230.4 | H9: 0 | I9: 0 | J9: =SUM(D9:I9) -> 1468.9 | K9: =K8+J9 -> 9506.05 | L9: 3676.4 | M9: =M8+L9 -> 20355.6 | N9: =J9-L9 -> -2207.5 | O9: =K9-M9 -> -10849.55 | P9: =20000+O9 -> 9150.45 | Q9: 140 | R9: 14
A10: 1 | B10: 芒种 | C10: 2 | D10: 1000 | E10: 100 | F10: =IF(C10>=1,VLOOKUP(R9+MAX(0,R10-R9-C10)+0,药材收益口径!$H$2:$I$222,2,FALSE),0)+IF(C10>=2,VLOOKUP(R9+MAX(0,R10-R9-C10)+1,药材收益口径!$H$2:$I$222,2,FALSE),0)+IF(C10>=3,VLOOKUP(R9+MAX(0,R10-R9-C10)+2,药材收益口径!$H$2:$I$222,2,FALSE),0)+IF(C10>=4,VLOOKUP(R9+MAX(0,R10-R9-C10)+3,药材收益口径!$H$2:$I$222,2,FALSE),0) -> 122.6 | G10: 230.4 | H10: 0 | I10: 1000 | J10: =SUM(D10:I10) -> 2453 | K10: =K9+J10 -> 11959.05 | L10: 2450 | M10: =M9+L10 -> 22805.6 | N10: =J10-L10 -> 3 | O10: =K10-M10 -> -10846.55 | P10: =20000+O10 -> 9153.45 | Q10: 160 | R10: 16 | S10: 022_02 敬亭治疗成功（银钱+1000）
A11: 1 | B11: 夏至 | C11: 2 | D11: 1000 | E11: 100 | F11: =IF(C11>=1,VLOOKUP(R10+MAX(0,R11-R10-C11)+0,药材收益口径!$H$2:$I$222,2,FALSE),0)+IF(C11>=2,VLOOKUP(R10+MAX(0,R11-R10-C11)+1,药材收益口径!$H$2:$I$222,2,FALSE),0)+IF(C11>=3,VLOOKUP(R10+MAX(0,R11-R10-C11)+2,药材收益口径!$H$2:$I$222,2,FALSE),0)+IF(C11>=4,VLOOKUP(R10+MAX(0,R11-R10-C11)+3,药材收益口径!$H$2:$I$222,2,FALSE),0) -> 122.6 | G11: 230.4 | H11: 0 | I11: 0 | J11: =SUM(D11:I11) -> 1453 | K11: =K10+J11 -> 13412.05 | L11: 3676.4 | M11: =M10+L11 -> 26482 | N11: =J11-L11 -> -2223.4 | O11: =K11-M11 -> -13069.95 | P11: =20000+O11 -> 6930.05 | Q11: 180 | R11: 18
A12: 1 | B12: 小暑 | C12: 2 | D12: 1000 | E12: 100 | F12: =IF(C12>=1,VLOOKUP(R11+MAX(0,R12-R11-C12)+0,药材收益口径!$H$2:$I$222,2,FALSE),0)+IF(C12>=2,VLOOKUP(R11+MAX(0,R12-R11-C12)+1,药材收益口径!$H$2:$I$222,2,FALSE),0)+IF(C12>=3,VLOOKUP(R11+MAX(0,R12-R11-C12)+2,药材收益口径!$H$2:$I$222,2,FALSE),0)+IF(C12>=4,VLOOKUP(R11+MAX(0,R12-R11-C12)+3,药材收益口径!$H$2:$I$222,2,FALSE),0) -> 119.38333 | G12: 230.4 | H12: 0 | I12: 0 | J12: =SUM(D12:I12) -> 1449.7833 | K12: =K11+J12 -> 14861.833 | L12: 2450 | M12: =M11+L12 -> 28932 | N12: =J12-L12 -> -1000.2167 | O12: =K12-M12 -> -14070.167 | P12: =20000+O12 -> 5929.8333 | Q12: 200 | R12: 20
A13: 1 | B13: 大暑 | C13: 2 | D13: 1000 | E13: 100 | F13: =IF(C13>=1,VLOOKUP(R12+MAX(0,R13-R12-C13)+0,药材收益口径!$H$2:$I$222,2,FALSE),0)+IF(C13>=2,VLOOKUP(R12+MAX(0,R13-R12-C13)+1,药材收益口径!$H$2:$I$222,2,FALSE),0)+IF(C13>=3,VLOOKUP(R12+MAX(0,R13-R12-C13)+2,药材收益口径!$H$2:$I$222,2,FALSE),0)+IF(C13>=4,VLOOKUP(R12+MAX(0,R13-R12-C13)+3,药材收益口径!$H$2:$I$222,2,FALSE),0) -> 119 | G13: 230.4 | H13: 5000 | I13: 0 | J13: =SUM(D13:I13) -> 6449.4 | K13: =K12+J13 -> 21311.233 | L13: 3276.4 | M13: =M12+L13 -> 32208.4 | N13: =J13-L13 -> 3173 | O13: =K13-M13 -> -10897.167 | P13: =20000+O13 -> 9102.8333 | Q13: 220 | R13: 22
A14: 1 | B14: 立秋 | C14: 2 | D14: 1000 | E14: 100 | F14: =IF(C14>=1,VLOOKUP(R13+MAX(0,R14-R13-C14)+0,药材收益口径!$H$2:$I$222,2,FALSE),0)+IF(C14>=2,VLOOKUP(R13+MAX(0,R14-R13-C14)+1,药材收益口径!$H$2:$I$222,2,FALSE),0)+IF(C14>=3,VLOOKUP(R13+MAX(0,R14-R13-C14)+2,药材收益口径!$H$2:$I$222,2,FALSE),0)+IF(C14>=4,VLOOKUP(R13+MAX(0,R14-R13-C14)+3,药材收益口径!$H$2:$I$222,2,FALSE),0) -> 124.0625 | G14: 230.4 | H14: 0 | I14: 0 | J14: =SUM(D14:I14) -> 1454.4625 | K14: =K13+J14 -> 22765.696 | L14: 2650 | M14: =M13+L14 -> 34858.4 | N14: =J14-L14 -> -1195.5375 | O14: =K14-M14 -> -12092.704 | P14: =20000+O14 -> 7907.2958 | Q14: 240 | R14: 24
A15: 1 | B15: 处暑 | C15: 2 | D15: 1000 | E15: 100 | F15: =IF(C15>=1,VLOOKUP(R14+MAX(0,R15-R14-C15)+0,药材收益口径!$H$2:$I$222,2,FALSE),0)+IF(C15>=2,VLOOKUP(R14+MAX(0,R15-R14-C15)+1,药材收益口径!$H$2:$I$222,2,FALSE),0)+IF(C15>=3,VLOOKUP(R14+MAX(0,R15-R14-C15)+2,药材收益口径!$H$2:$I$222,2,FALSE),0)+IF(C15>=4,VLOOKUP(R14+MAX(0,R15-R14-C15)+3,药材收益口径!$H$2:$I$222,2,FALSE),0) -> 198.39583 | G15: 230.4 | H15: 0 | I15: 0 | J15: =SUM(D15:I15) -> 1528.7958 | K15: =K14+J15 -> 24294.492 | L15: 4776.4 | M15: =M14+L15 -> 39634.8 | N15: =J15-L15 -> -3247.6042 | O15: =K15-M15 -> -15340.308 | P15: =20000+O15 -> 4659.6917 | Q15: 260 | R15: 26
A16: 1 | B16: 白露 | C16: 2 | D16: 1000 | E16: 100 | F16: =IF(C16>=1,VLOOKUP(R15+MAX(0,R16-R15-C16)+0,药材收益口径!$H$2:$I$222,2,FALSE),0)+IF(C16>=2,VLOOKUP(R15+MAX(0,R16-R15-C16)+1,药材收益口径!$H$2:$I$222,2,FALSE),0)+IF(C16>=3,VLOOKUP(R15+MAX(0,R16-R15-C16)+2,药材收益口径!$H$2:$I$222,2,FALSE),0)+IF(C16>=4,VLOOKUP(R15+MAX(0,R16-R15-C16)+3,药材收益口径!$H$2:$I$222,2,FALSE),0) -> 234.27273 | G16: 230.4 | H16: 0 | I16: 0 | J16: =SUM(D16:I16) -> 1564.6727 | K16: =K15+J16 -> 25859.164 | L16: 1550 | M16: =M15+L16 -> 41184.8 | N16: =J16-L16 -> 14.672727 | O16: =K16-M16 -> -15325.636 | P16: =20000+O16 -> 4674.3644 | Q16: 280 | R16: 28
A17: 1 | B17: 秋分 | C17: 2 | D17: 1000 | E17: 100 | F17: =IF(C17>=1,VLOOKUP(R16+MAX(0,R17-R16-C17)+0,药材收益口径!$H$2:$I$222,2,FALSE),0)+IF(C17>=2,VLOOKUP(R16+MAX(0,R17-R16-C17)+1,药材收益口径!$H$2:$I$222,2,FALSE),0)+IF(C17>=3,VLOOKUP(R16+MAX(0,R17-R16-C17)+2,药材收益口径!$H$2:$I$222,2,FALSE),0)+IF(C17>=4,VLOOKUP(R16+MAX(0,R17-R16-C17)+3,药材收益口径!$H$2:$I$222,2,FALSE),0) -> 215.46154 | G17: 230.4 | H17: 0 | I17: 0 | J17: =SUM(D17:I17) -> 1545.8615 | K17: =K16+J17 -> 27405.026 | L17: 3376.4 | M17: =M16+L17 -> 44561.2 | N17: =J17-L17 -> -1830.5385 | O17: =K17-M17 -> -17156.174 | P17: =20000+O17 -> 2843.8259 | Q17: 300 | R17: 30
A18: 1 | B18: 寒露 | C18: 2 | D18: 1000 | E18: 250 | F18: =IF(C18>=1,VLOOKUP(R17+MAX(0,R18-R17-C18)+0,药材收益口径!$H$2:$I$222,2,FALSE),0)+IF(C18>=2,VLOOKUP(R17+MAX(0,R18-R17-C18)+1,药材收益口径!$H$2:$I$222,2,FALSE),0)+IF(C18>=3,VLOOKUP(R17+MAX(0,R18-R17-C18)+2,药材收益口径!$H$2:$I$222,2,FALSE),0)+IF(C18>=4,VLOOKUP(R17+MAX(0,R18-R17-C18)+3,药材收益口径!$H$2:$I$222,2,FALSE),0) -> 215.46154 | G18: 230.4 | H18: 0 | I18: 0 | J18: =SUM(D18:I18) -> 1695.8615 | K18: =K17+J18 -> 29100.887 | L18: 1550 | M18: =M17+L18 -> 46111.2 | N18: =J18-L18 -> 145.86154 | O18: =K18-M18 -> -17010.313 | P18: =20000+O18 -> 2989.6875 | Q18: 320 | R18: 32
A19: 1 | B19: 霜降 | C19: 2 | D19: 1000 | E19: 400 | F19: =IF(C19>=1,VLOOKUP(R18+MAX(0,R19-R18-C19)+0,药材收益口径!$H$2:$I$222,2,FALSE),0)+IF(C19>=2,VLOOKUP(R18+MAX(0,R19-R18-C19)+1,药材收益口径!$H$2:$I$222,2,FALSE),0)+IF(C19>=3,VLOOKUP(R18+MAX(0,R19-R18-C19)+2,药材收益口径!$H$2:$I$222,2,FALSE),0)+IF(C19>=4,VLOOKUP(R18+MAX(0,R19-R18-C19)+3,药材收益口径!$H$2:$I$222,2,FALSE),0) -> 213.98077 | G19: 230.4 | H19: 15000 | I19: 0 | J19: =SUM(D19:I19) -> 16844.381 | K19: =K18+J19 -> 45945.268 | L19: 4276.4 | M19: =M18+L19 -> 50387.6 | N19: =J19-L19 -> 12567.981 | O19: =K19-M19 -> -4442.3318 | P19: =20000+O19 -> 15557.668 | Q19: 340 | R19: 34
A20: 1 | B20: 立冬 | C20: 2 | D20: 1000 | E20: 400 | F20: =IF(C20>=1,VLOOKUP(R19+MAX(0,R20-R19-C20)+0,药材收益口径!$H$2:$I$222,2,FALSE),0)+IF(C20>=2,VLOOKUP(R19+MAX(0,R20-R19-C20)+1,药材收益口径!$H$2:$I$222,2,FALSE),0)+IF(C20>=3,VLOOKUP(R19+MAX(0,R20-R19-C20)+2,药材收益口径!$H$2:$I$222,2,FALSE),0)+IF(C20>=4,VLOOKUP(R19+MAX(0,R20-R19-C20)+3,药材收益口径!$H$2:$I$222,2,FALSE),0) -> 210.35 | G20: 230.4 | H20: 0 | I20: 0 | J20: =SUM(D20:I20) -> 1840.75 | K20: =K19+J20 -> 47786.018 | L20: 4750 | M20: =M19+L20 -> 55137.6 | N20: =J20-L20 -> -2909.25 | O20: =K20-M20 -> -7351.5818 | P20: =20000+O20 -> 12648.418 | Q20: 360 | R20: 36
A21: 1 | B21: 小雪 | C21: 2 | D21: 1000 | E21: 400 | F21: =IF(C21>=1,VLOOKUP(R20+MAX(0,R21-R20-C21)+0,药材收益口径!$H$2:$I$222,2,FALSE),0)+IF(C21>=2,VLOOKUP(R20+MAX(0,R21-R20-C21)+1,药材收益口径!$H$2:$I$222,2,FALSE),0)+IF(C21>=3,VLOOKUP(R20+MAX(0,R21-R20-C21)+2,药材收益口径!$H$2:$I$222,2,FALSE),0)+IF(C21>=4,VLOOKUP(R20+MAX(0,R21-R20-C21)+3,药材收益口径!$H$2:$I$222,2,FALSE),0) -> 210.40625 | G21: 230.4 | H21: 0 | I21: 0 | J21: =SUM(D21:I21) -> 1840.8063 | K21: =K20+J21 -> 49626.824 | L21: 2776.4 | M21: =M20+L21 -> 57914 | N21: =J21-L21 -> -935.59375 | O21: =K21-M21 -> -8287.1755 | P21: =20000+O21 -> 11712.824 | Q21: 380 | R21: 38
A22: 1 | B22: 大雪 | C22: 2 | D22: 1000 | E22: 400 | F22: =IF(C22>=1,VLOOKUP(R21+MAX(0,R22-R21-C22)+0,药材收益口径!$H$2:$I$222,2,FALSE),0)+IF(C22>=2,VLOOKUP(R21+MAX(0,R22-R21-C22)+1,药材收益口径!$H$2:$I$222,2,FALSE),0)+IF(C22>=3,VLOOKUP(R21+MAX(0,R22-R21-C22)+2,药材收益口径!$H$2:$I$222,2,FALSE),0)+IF(C22>=4,VLOOKUP(R21+MAX(0,R22-R21-C22)+3,药材收益口径!$H$2:$I$222,2,FALSE),0) -> 207 | G22: 230.4 | H22: 0 | I22: 0 | J22: =SUM(D22:I22) -> 1837.4 | K22: =K21+J22 -> 51464.224 | L22: 1550 | M22: =M21+L22 -> 59464 | N22: =J22-L22 -> 287.4 | O22: =K22-M22 -> -7999.7755 | P22: =20000+O22 -> 12000.224 | Q22: 400 | R22: 40
A23: 1 | B23: 冬至 | C23: 2 | D23: 1000 | E23: 400 | F23: =IF(C23>=1,VLOOKUP(R22+MAX(0,R23-R22-C23)+0,药材收益口径!$H$2:$I$222,2,FALSE),0)+IF(C23>=2,VLOOKUP(R22+MAX(0,R23-R22-C23)+1,药材收益口径!$H$2:$I$222,2,FALSE),0)+IF(C23>=3,VLOOKUP(R22+MAX(0,R23-R22-C23)+2,药材收益口径!$H$2:$I$222,2,FALSE),0)+IF(C23>=4,VLOOKUP(R22+MAX(0,R23-R22-C23)+3,药材收益口径!$H$2:$I$222,2,FALSE),0) -> 214.94444 | G23: 230.4 | H23: 0 | I23: 1000 | J23: =SUM(D23:I23) -> 2845.3444 | K23: =K22+J23 -> 54309.569 | L23: 2776.4 | M23: =M22+L23 -> 62240.4 | N23: =J23-L23 -> 68.944444 | O23: =K23-M23 -> -7930.8311 | P23: =20000+O23 -> 12069.169 | Q23: 420 | R23: 42 | S23: 023_02 谢飞燕肺气虚（银钱+1000）
A24: 1 | B24: 小寒 | C24: 2 | D24: 1000 | E24: 400 | F24: =IF(C24>=1,VLOOKUP(R23+MAX(0,R24-R23-C24)+0,药材收益口径!$H$2:$I$222,2,FALSE),0)+IF(C24>=2,VLOOKUP(R23+MAX(0,R24-R23-C24)+1,药材收益口径!$H$2:$I$222,2,FALSE),0)+IF(C24>=3,VLOOKUP(R23+MAX(0,R24-R23-C24)+2,药材收益口径!$H$2:$I$222,2,FALSE),0)+IF(C24>=4,VLOOKUP(R23+MAX(0,R24-R23-C24)+3,药材收益口径!$H$2:$I$222,2,FALSE),0) -> 214.94444 | G24: 230.4 | H24: 0 | I24: 0 | J24: =SUM(D24:I24) -> 1845.3444 | K24: =K23+J24 -> 56154.913 | L24: 1550 | M24: =M23+L24 -> 63790.4 | N24: =J24-L24 -> 295.34444 | O24: =K24-M24 -> -7635.4866 | P24: =20000+O24 -> 12364.513 | Q24: 440 | R24: 44
A25: 1 | B25: 大寒 | C25: 2 | D25: 1000 | E25: 400 | F25: =IF(C25>=1,VLOOKUP(R24+MAX(0,R25-R24-C25)+0,药材收益口径!$H$2:$I$222,2,FALSE),0)+IF(C25>=2,VLOOKUP(R24+MAX(0,R25-R24-C25)+1,药材收益口径!$H$2:$I$222,2,FALSE),0)+IF(C25>=3,VLOOKUP(R24+MAX(0,R25-R24-C25)+2,药材收益口径!$H$2:$I$222,2,FALSE),0)+IF(C25>=4,VLOOKUP(R24+MAX(0,R25-R24-C25)+3,药材收益口径!$H$2:$I$222,2,FALSE),0) -> 209.94737 | G25: 230.4 | H25: 0 | I25: 1000 | J25: =SUM(D25:I25) -> 2840.3474 | K25: =K24+J25 -> 58995.261 | L25: 3376.4 | M25: =M24+L25 -> 67166.8 | N25: =J25-L25 -> -536.05263 | O25: =K25-M25 -> -8171.5393 | P25: =20000+O25 -> 11828.461 | Q25: 460 | R25: 46 | S25: 024_02 谢飞燕肺阴虚（银钱+1000）
A26: 2 | B26: 立春 | C26: 2 | D26: 1000 | E26: 400 | F26: =IF(C26>=1,VLOOKUP(R25+MAX(0,R26-R25-C26)+0,药材收益口径!$H$2:$I$222,2,FALSE),0)+IF(C26>=2,VLOOKUP(R25+MAX(0,R26-R25-C26)+1,药材收益口径!$H$2:$I$222,2,FALSE),0)+IF(C26>=3,VLOOKUP(R25+MAX(0,R26-R25-C26)+2,药材收益口径!$H$2:$I$222,2,FALSE),0)+IF(C26>=4,VLOOKUP(R25+MAX(0,R26-R25-C26)+3,药材收益口径!$H$2:$I$222,2,FALSE),0) -> 209.94737 | G26: 230.4 | H26: 0 | I26: 0 | J26: =SUM(D26:I26) -> 1840.3474 | K26: =K25+J26 -> 60835.608 | L26: 2650 | M26: =M25+L26 -> 69816.8 | N26: =J26-L26 -> -809.65263 | O26: =K26-M26 -> -8981.1919 | P26: =20000+O26 -> 11018.808 | Q26: 480 | R26: 48
A27: 2 | B27: 雨水 | C27: 2 | D27: 1000 | E27: 400 | F27: =IF(C27>=1,VLOOKUP(R26+MAX(0,R27-R26-C27)+0,药材收益口径!$H$2:$I$222,2,FALSE),0)+IF(C27>=2,VLOOKUP(R26+MAX(0,R27-R26-C27)+1,药材收益口径!$H$2:$I$222,2,FALSE),0)+IF(C27>=3,VLOOKUP(R26+MAX(0,R27-R26-C27)+2,药材收益口径!$H$2:$I$222,2,FALSE),0)+IF(C27>=4,VLOOKUP(R26+MAX(0,R27-R26-C27)+3,药材收益口径!$H$2:$I$222,2,FALSE),0) -> 243.27262 | G27: 230.4 | H27: 0 | I27: 0 | J27: =SUM(D27:I27) -> 1873.6726 | K27: =K26+J27 -> 62709.281 | L27: 2776.4 | M27: =M26+L27 -> 72593.2 | N27: =J27-L27 -> -902.72738 | O27: =K27-M27 -> -9883.9193 | P27: =20000+O27 -> 10116.081 | Q27: 500 | R27: 50
A28: 2 | B28: 惊蛰 | C28: 2 | D28: 1000 | E28: 400 | F28: =IF(C28>=1,VLOOKUP(R27+MAX(0,R28-R27-C28)+0,药材收益口径!$H$2:$I$222,2,FALSE),0)+IF(C28>=2,VLOOKUP(R27+MAX(0,R28-R27-C28)+1,药材收益口径!$H$2:$I$222,2,FALSE),0)+IF(C28>=3,VLOOKUP(R27+MAX(0,R28-R27-C28)+2,药材收益口径!$H$2:$I$222,2,FALSE),0)+IF(C28>=4,VLOOKUP(R27+MAX(0,R28-R27-C28)+3,药材收益口径!$H$2:$I$222,2,FALSE),0) -> 247.47917 | G28: 230.4 | H28: 0 | I28: 1000 | J28: =SUM(D28:I28) -> 2877.8792 | K28: =K27+J28 -> 65587.16 | L28: 1550 | M28: =M27+L28 -> 74143.2 | N28: =J28-L28 -> 1327.8792 | O28: =K28-M28 -> -8556.0401 | P28: =20000+O28 -> 11443.96 | Q28: 1520 | R28: 59 | S28: 024_04 王百堂来访（心得+7）；005_02 治愈世子（银钱+1000，名望+1000）
A29: 2 | B29: 春分 | C29: 2 | D29: 1000 | E29: 1000 | F29: =IF(C29>=1,VLOOKUP(R28+MAX(0,R29-R28-C29)+0,药材收益口径!$H$2:$I$222,2,FALSE),0)+IF(C29>=2,VLOOKUP(R28+MAX(0,R29-R28-C29)+1,药材收益口径!$H$2:$I$222,2,FALSE),0)+IF(C29>=3,VLOOKUP(R28+MAX(0,R29-R28-C29)+2,药材收益口径!$H$2:$I$222,2,FALSE),0)+IF(C29>=4,VLOOKUP(R28+MAX(0,R29-R28-C29)+3,药材收益口径!$H$2:$I$222,2,FALSE),0) -> 240.17877 | G29: 230.4 | H29: 0 | I29: 0 | J29: =SUM(D29:I29) -> 2470.5788 | K29: =K28+J29 -> 68057.739 | L29: 3376.4 | M29: =M28+L29 -> 77519.6 | N29: =J29-L29 -> -905.82123 | O29: =K29-M29 -> -9461.8613 | P29: =20000+O29 -> 10538.139 | Q29: 1540 | R29: 61
A30: 2 | B30: 清明 | C30: 2 | D30: 1000 | E30: 1000 | F30: =IF(C30>=1,VLOOKUP(R29+MAX(0,R30-R29-C30)+0,药材收益口径!$H$2:$I$222,2,FALSE),0)+IF(C30>=2,VLOOKUP(R29+MAX(0,R30-R29-C30)+1,药材收益口径!$H$2:$I$222,2,FALSE),0)+IF(C30>=3,VLOOKUP(R29+MAX(0,R30-R29-C30)+2,药材收益口径!$H$2:$I$222,2,FALSE),0)+IF(C30>=4,VLOOKUP(R29+MAX(0,R30-R29-C30)+3,药材收益口径!$H$2:$I$222,2,FALSE),0) -> 235.54828 | G30: 230.4 | H30: 0 | I30: 0 | J30: =SUM(D30:I30) -> 2465.9483 | K30: =K29+J30 -> 70523.687 | L30: 3550 | M30: =M29+L30 -> 81069.6 | N30: =J30-L30 -> -1084.0517 | O30: =K30-M30 -> -10545.913 | P30: =20000+O30 -> 9454.087 | Q30: 1560 | R30: 63
A31: 2 | B31: 谷雨 | C31: 2 | D31: 1000 | E31: 1000 | F31: =IF(C31>=1,VLOOKUP(R30+MAX(0,R31-R30-C31)+0,药材收益口径!$H$2:$I$222,2,FALSE),0)+IF(C31>=2,VLOOKUP(R30+MAX(0,R31-R30-C31)+1,药材收益口径!$H$2:$I$222,2,FALSE),0)+IF(C31>=3,VLOOKUP(R30+MAX(0,R31-R30-C31)+2,药材收益口径!$H$2:$I$222,2,FALSE),0)+IF(C31>=4,VLOOKUP(R30+MAX(0,R31-R30-C31)+3,药材收益口径!$H$2:$I$222,2,FALSE),0) -> 234.39286 | G31: 230.4 | H31: 0 | I31: 0 | J31: =SUM(D31:I31) -> 2464.7929 | K31: =K30+J31 -> 72988.48 | L31: 2776.4 | M31: =M30+L31 -> 83846 | N31: =J31-L31 -> -311.60714 | O31: =K31-M31 -> -10857.52 | P31: =20000+O31 -> 9142.4798 | Q31: 1580 | R31: 65
A32: 2 | B32: 立夏 | C32: 2 | D32: 1000 | E32: 1000 | F32: =IF(C32>=1,VLOOKUP(R31+MAX(0,R32-R31-C32)+0,药材收益口径!$H$2:$I$222,2,FALSE),0)+IF(C32>=2,VLOOKUP(R31+MAX(0,R32-R31-C32)+1,药材收益口径!$H$2:$I$222,2,FALSE),0)+IF(C32>=3,VLOOKUP(R31+MAX(0,R32-R31-C32)+2,药材收益口径!$H$2:$I$222,2,FALSE),0)+IF(C32>=4,VLOOKUP(R31+MAX(0,R32-R31-C32)+3,药材收益口径!$H$2:$I$222,2,FALSE),0) -> 234.39286 | G32: 230.4 | H32: 0 | I32: 0 | J32: =SUM(D32:I32) -> 2464.7929 | K32: =K31+J32 -> 75453.273 | L32: 2650 | M32: =M31+L32 -> 86496 | N32: =J32-L32 -> -185.20714 | O32: =K32-M32 -> -11042.727 | P32: =20000+O32 -> 8957.2727 | Q32: 1600 | R32: 67
A33: 2 | B33: 小满 | C33: 2 | D33: 1000 | E33: 1000 | F33: =IF(C33>=1,VLOOKUP(R32+MAX(0,R33-R32-C33)+0,药材收益口径!$H$2:$I$222,2,FALSE),0)+IF(C33>=2,VLOOKUP(R32+MAX(0,R33-R32-C33)+1,药材收益口径!$H$2:$I$222,2,FALSE),0)+IF(C33>=3,VLOOKUP(R32+MAX(0,R33-R32-C33)+2,药材收益口径!$H$2:$I$222,2,FALSE),0)+IF(C33>=4,VLOOKUP(R32+MAX(0,R33-R32-C33)+3,药材收益口径!$H$2:$I$222,2,FALSE),0) -> 248.58621 | G33: 230.4 | H33: 0 | I33: 0 | J33: =SUM(D33:I33) -> 2478.9862 | K33: =K32+J33 -> 77932.259 | L33: 3676.4 | M33: =M32+L33 -> 90172.4 | N33: =J33-L33 -> -1197.4138 | O33: =K33-M33 -> -12240.141 | P33: =20000+O33 -> 7759.8589 | Q33: 1620 | R33: 69
A34: 2 | B34: 芒种 | C34: 2 | D34: 1000 | E34: 1000 | F34: =IF(C34>=1,VLOOKUP(R33+MAX(0,R34-R33-C34)+0,药材收益口径!$H$2:$I$222,2,FALSE),0)+IF(C34>=2,VLOOKUP(R33+MAX(0,R34-R33-C34)+1,药材收益口径!$H$2:$I$222,2,FALSE),0)+IF(C34>=3,VLOOKUP(R33+MAX(0,R34-R33-C34)+2,药材收益口径!$H$2:$I$222,2,FALSE),0)+IF(C34>=4,VLOOKUP(R33+MAX(0,R34-R33-C34)+3,药材收益口径!$H$2:$I$222,2,FALSE),0) -> 248.58621 | G34: 230.4 | H34: 0 | I34: 0 | J34: =SUM(D34:I34) -> 2478.9862 | K34: =K33+J34 -> 80411.245 | L34: 2450 | M34: =M33+L34 -> 92622.4 | N34: =J34-L34 -> 28.986207 | O34: =K34-M34 -> -12211.155 | P34: =20000+O34 -> 7788.8451 | Q34: 1640 | R34: 71
A35: 2 | B35: 夏至 | C35: 2 | D35: 1000 | E35: 1000 | F35: =IF(C35>=1,VLOOKUP(R34+MAX(0,R35-R34-C35)+0,药材收益口径!$H$2:$I$222,2,FALSE),0)+IF(C35>=2,VLOOKUP(R34+MAX(0,R35-R34-C35)+1,药材收益口径!$H$2:$I$222,2,FALSE),0)+IF(C35>=3,VLOOKUP(R34+MAX(0,R35-R34-C35)+2,药材收益口径!$H$2:$I$222,2,FALSE),0)+IF(C35>=4,VLOOKUP(R34+MAX(0,R35-R34-C35)+3,药材收益口径!$H$2:$I$222,2,FALSE),0) -> 246.43826 | G35: 230.4 | H35: 0 | I35: 0 | J35: =SUM(D35:I35) -> 2476.8383 | K35: =K34+J35 -> 82888.083 | L35: 3676.4 | M35: =M34+L35 -> 96298.8 | N35: =J35-L35 -> -1199.5617 | O35: =K35-M35 -> -13410.717 | P35: =20000+O35 -> 6589.2833 | Q35: 1660 | R35: 73
A36: 2 | B36: 小暑 | C36: 2 | D36: 1000 | E36: 1000 | F36: =IF(C36>=1,VLOOKUP(R35+MAX(0,R36-R35-C36)+0,药材收益口径!$H$2:$I$222,2,FALSE),0)+IF(C36>=2,VLOOKUP(R35+MAX(0,R36-R35-C36)+1,药材收益口径!$H$2:$I$222,2,FALSE),0)+IF(C36>=3,VLOOKUP(R35+MAX(0,R36-R35-C36)+2,药材收益口径!$H$2:$I$222,2,FALSE),0)+IF(C36>=4,VLOOKUP(R35+MAX(0,R36-R35-C36)+3,药材收益口径!$H$2:$I$222,2,FALSE),0) -> 244.29032 | G36: 230.4 | H36: 0 | I36: 0 | J36: =SUM(D36:I36) -> 2474.6903 | K36: =K35+J36 -> 85362.774 | L36: 2450 | M36: =M35+L36 -> 98748.8 | N36: =J36-L36 -> 24.690323 | O36: =K36-M36 -> -13386.026 | P36: =20000+O36 -> 6613.9737 | Q36: 1680 | R36: 75
A37: 2 | B37: 大暑 | C37: 2 | D37: 1000 | E37: 1000 | F37: =IF(C37>=1,VLOOKUP(R36+MAX(0,R37-R36-C37)+0,药材收益口径!$H$2:$I$222,2,FALSE),0)+IF(C37>=2,VLOOKUP(R36+MAX(0,R37-R36-C37)+1,药材收益口径!$H$2:$I$222,2,FALSE),0)+IF(C37>=3,VLOOKUP(R36+MAX(0,R37-R36-C37)+2,药材收益口径!$H$2:$I$222,2,FALSE),0)+IF(C37>=4,VLOOKUP(R36+MAX(0,R37-R36-C37)+3,药材收益口径!$H$2:$I$222,2,FALSE),0) -> 285.8982 | G37: 230.4 | H37: 5000 | I37: 0 | J37: =SUM(D37:I37) -> 7516.2982 | K37: =K36+J37 -> 92879.072 | L37: 3276.4 | M37: =M36+L37 -> 102025.2 | N37: =J37-L37 -> 4239.8982 | O37: =K37-M37 -> -9146.1281 | P37: =20000+O37 -> 10853.872 | Q37: 1700 | R37: 77
A38: 2 | B38: 立秋 | C38: 2 | D38: 1000 | E38: 1000 | F38: =IF(C38>=1,VLOOKUP(R37+MAX(0,R38-R37-C38)+0,药材收益口径!$H$2:$I$222,2,FALSE),0)+IF(C38>=2,VLOOKUP(R37+MAX(0,R38-R37-C38)+1,药材收益口径!$H$2:$I$222,2,FALSE),0)+IF(C38>=3,VLOOKUP(R37+MAX(0,R38-R37-C38)+2,药材收益口径!$H$2:$I$222,2,FALSE),0)+IF(C38>=4,VLOOKUP(R37+MAX(0,R38-R37-C38)+3,药材收益口径!$H$2:$I$222,2,FALSE),0) -> 291.09581 | G38: 230.4 | H38: 0 | I38: 0 | J38: =SUM(D38:I38) -> 2521.4958 | K38: =K37+J38 -> 95400.568 | L38: 2650 | M38: =M37+L38 -> 104675.2 | N38: =J38-L38 -> -128.50419 | O38: =K38-M38 -> -9274.6323 | P38: =20000+O38 -> 10725.368 | Q38: 1720 | R38: 79
A39: 2 | B39: 处暑 | C39: 2 | D39: 1000 | E39: 1000 | F39: =IF(C39>=1,VLOOKUP(R38+MAX(0,R39-R38-C39)+0,药材收益口径!$H$2:$I$222,2,FALSE),0)+IF(C39>=2,VLOOKUP(R38+MAX(0,R39-R38-C39)+1,药材收益口径!$H$2:$I$222,2,FALSE),0)+IF(C39>=3,VLOOKUP(R38+MAX(0,R39-R38-C39)+2,药材收益口径!$H$2:$I$222,2,FALSE),0)+IF(C39>=4,VLOOKUP(R38+MAX(0,R39-R38-C39)+3,药材收益口径!$H$2:$I$222,2,FALSE),0) -> 297.67647 | G39: 230.4 | H39: 0 | I39: 0 | J39: =SUM(D39:I39) -> 2528.0765 | K39: =K38+J39 -> 97928.644 | L39: 4776.4 | M39: =M38+L39 -> 109451.6 | N39: =J39-L39 -> -2248.3235 | O39: =K39-M39 -> -11522.956 | P39: =20000+O39 -> 8477.0442 | Q39: 1740 | R39: 81
A40: 2 | B40: 白露 | C40: 2 | D40: 1000 | E40: 1000 | F40: =IF(C40>=1,VLOOKUP(R39+MAX(0,R40-R39-C40)+0,药材收益口径!$H$2:$I$222,2,FALSE),0)+IF(C40>=2,VLOOKUP(R39+MAX(0,R40-R39-C40)+1,药材收益口径!$H$2:$I$222,2,FALSE),0)+IF(C40>=3,VLOOKUP(R39+MAX(0,R40-R39-C40)+2,药材收益口径!$H$2:$I$222,2,FALSE),0)+IF(C40>=4,VLOOKUP(R39+MAX(0,R40-R39-C40)+3,药材收益口径!$H$2:$I$222,2,FALSE),0) -> 297.17143 | G40: 230.4 | H40: 0 | I40: 0 | J40: =SUM(D40:I40) -> 2527.5714 | K40: =K39+J40 -> 100456.22 | L40: 1550 | M40: =M39+L40 -> 111001.6 | N40: =J40-L40 -> 977.57143 | O40: =K40-M40 -> -10545.384 | P40: =20000+O40 -> 9454.6156 | Q40: 1760 | R40: 83
...

Sheet 普通
A1: 年份 | B1: 节气 | C1: 妙手回春次数 | D1: 李言闻收入 | E1: 诊费预期 | F1: 药材净收入预期 | G1: 谢仪预期 | H1: 田租 | I1: 剧情银钱奖励 | J1: 预期收入 | K1: 累计预期收入 | L1: 预期支出 | M1: 累计预期支出 | N1: 本节气收支差 | O1: 累计收支差 | P1: 含初始资金余额 | Q1: 节气末名望 | R1: 节气末心得 | S1: 剧情备注
A2: 1 | B2: 立春 | C2: 0 | D2: 0 | E2: 0 | F2: =IF(C2>=1,VLOOKUP(0+MAX(0,R2-0-C2)+0,药材收益口径!$H$2:$I$222,2,FALSE),0)+IF(C2>=2,VLOOKUP(0+MAX(0,R2-0-C2)+1,药材收益口径!$H$2:$I$222,2,FALSE),0)+IF(C2>=3,VLOOKUP(0+MAX(0,R2-0-C2)+2,药材收益口径!$H$2:$I$222,2,FALSE),0)+IF(C2>=4,VLOOKUP(0+MAX(0,R2-0-C2)+3,药材收益口径!$H$2:$I$222,2,FALSE),0) -> 0 | G2: 0 | H2: 0 | I2: 0 | J2: =SUM(D2:I2) -> 0 | K2: =J2 -> 0 | L2: =K2 -> 0 | M2: =L2 -> 0 | N2: =J2-L2 -> 0 | O2: =K2-M2 -> 0 | P2: =20000+O2 -> 20000 | Q2: 0 | R2: 0
A3: 1 | B3: 雨水 | C3: 3 | D3: 500 | E3: 60 | F3: =IF(C3>=1,VLOOKUP(R2+MAX(0,R3-R2-C3)+0,药材收益口径!$H$2:$I$222,2,FALSE),0)+IF(C3>=2,VLOOKUP(R2+MAX(0,R3-R2-C3)+1,药材收益口径!$H$2:$I$222,2,FALSE),0)+IF(C3>=3,VLOOKUP(R2+MAX(0,R3-R2-C3)+2,药材收益口径!$H$2:$I$222,2,FALSE),0)+IF(C3>=4,VLOOKUP(R2+MAX(0,R3-R2-C3)+3,药材收益口径!$H$2:$I$222,2,FALSE),0) -> 59 | G3: 345.6 | H3: 0 | I3: 0 | J3: =SUM(D3:I3) -> 964.6 | K3: =K2+J3 -> 964.6 | L3: 2776.4 | M3: =M2+L3 -> 2776.4 | N3: =J3-L3 -> -1811.8 | O3: =K3-M3 -> -1811.8 | P3: =20000+O3 -> 18188.2 | Q3: 30 | R3: 3
A4: 1 | B4: 惊蛰 | C4: 3 | D4: 500 | E4: 60 | F4: =IF(C4>=1,VLOOKUP(R3+MAX(0,R4-R3-C4)+0,药材收益口径!$H$2:$I$222,2,FALSE),0)+IF(C4>=2,VLOOKUP(R3+MAX(0,R4-R3-C4)+1,药材收益口径!$H$2:$I$222,2,FALSE),0)+IF(C4>=3,VLOOKUP(R3+MAX(0,R4-R3-C4)+2,药材收益口径!$H$2:$I$222,2,FALSE),0)+IF(C4>=4,VLOOKUP(R3+MAX(0,R4-R3-C4)+3,药材收益口径!$H$2:$I$222,2,FALSE),0) -> 59 | G4: 345.6 | H4: 0 | I4: 0 | J4: =SUM(D4:I4) -> 964.6 | K4: =K3+J4 -> 1929.2 | L4: 1550 | M4: =M3+L4 -> 4326.4 | N4: =J4-L4 -> -585.4 | O4: =K4-M4 -> -2397.2 | P4: =20000+O4 -> 17602.8 | Q4: 60 | R4: 6
A5: 1 | B5: 春分 | C5: 3 | D5: 500 | E5: 60 | F5: =IF(C5>=1,VLOOKUP(R4+MAX(0,R5-R4-C5)+0,药材收益口径!$H$2:$I$222,2,FALSE),0)+IF(C5>=2,VLOOKUP(R4+MAX(0,R5-R4-C5)+1,药材收益口径!$H$2:$I$222,2,FALSE),0)+IF(C5>=3,VLOOKUP(R4+MAX(0,R5-R4-C5)+2,药材收益口径!$H$2:$I$222,2,FALSE),0)+IF(C5>=4,VLOOKUP(R4+MAX(0,R5-R4-C5)+3,药材收益口径!$H$2:$I$222,2,FALSE),0) -> 59 | G5: 345.6 | H5: 0 | I5: 0 | J5: =SUM(D5:I5) -> 964.6 | K5: =K4+J5 -> 2893.8 | L5: 3376.4 | M5: =M4+L5 -> 7702.8 | N5: =J5-L5 -> -2411.8 | O5: =K5-M5 -> -4809 | P5: =20000+O5 -> 15191 | Q5: 90 | R5: 9
A6: 1 | B6: 清明 | C6: 3 | D6: 500 | E6: 90 | F6: =IF(C6>=1,VLOOKUP(R5+MAX(0,R6-R5-C6)+0,药材收益口径!$H$2:$I$222,2,FALSE),0)+IF(C6>=2,VLOOKUP(R5+MAX(0,R6-R5-C6)+1,药材收益口径!$H$2:$I$222,2,FALSE),0)+IF(C6>=3,VLOOKUP(R5+MAX(0,R6-R5-C6)+2,药材收益口径!$H$2:$I$222,2,FALSE),0)+IF(C6>=4,VLOOKUP(R5+MAX(0,R6-R5-C6)+3,药材收益口径!$H$2:$I$222,2,FALSE),0) -> 207.75 | G6: 345.6 | H6: 0 | I6: 0 | J6: =SUM(D6:I6) -> 1143.35 | K6: =K5+J6 -> 4037.15 | L6: 3550 | M6: =M5+L6 -> 11252.8 | N6: =J6-L6 -> -2406.65 | O6: =K6-M6 -> -7215.65 | P6: =20000+O6 -> 12784.35 | Q6: 120 | R6: 12
A7: 1 | B7: 谷雨 | C7: 3 | D7: 500 | E7: 150 | F7: =IF(C7>=1,VLOOKUP(R6+MAX(0,R7-R6-C7)+0,药材收益口径!$H$2:$I$222,2,FALSE),0)+IF(C7>=2,VLOOKUP(R6+MAX(0,R7-R6-C7)+1,药材收益口径!$H$2:$I$222,2,FALSE),0)+IF(C7>=3,VLOOKUP(R6+MAX(0,R7-R6-C7)+2,药材收益口径!$H$2:$I$222,2,FALSE),0)+IF(C7>=4,VLOOKUP(R6+MAX(0,R7-R6-C7)+3,药材收益口径!$H$2:$I$222,2,FALSE),0) -> 199.8 | G7: 345.6 | H7: 0 | I7: 0 | J7: =SUM(D7:I7) -> 1195.4 | K7: =K6+J7 -> 5232.55 | L7: 2776.4 | M7: =M6+L7 -> 14029.2 | N7: =J7-L7 -> -1581 | O7: =K7-M7 -> -8796.65 | P7: =20000+O7 -> 11203.35 | Q7: 150 | R7: 15
A8: 1 | B8: 立夏 | C8: 3 | D8: 500 | E8: 150 | F8: =IF(C8>=1,VLOOKUP(R7+MAX(0,R8-R7-C8)+0,药材收益口径!$H$2:$I$222,2,FALSE),0)+IF(C8>=2,VLOOKUP(R7+MAX(0,R8-R7-C8)+1,药材收益口径!$H$2:$I$222,2,FALSE),0)+IF(C8>=3,VLOOKUP(R7+MAX(0,R8-R7-C8)+2,药材收益口径!$H$2:$I$222,2,FALSE),0)+IF(C8>=4,VLOOKUP(R7+MAX(0,R8-R7-C8)+3,药材收益口径!$H$2:$I$222,2,FALSE),0) -> 183.9 | G8: 345.6 | H8: 0 | I8: 1000 | J8: =SUM(D8:I8) -> 2179.5 | K8: =K7+J8 -> 7412.05 | L8: 2650 | M8: =M7+L8 -> 16679.2 | N8: =J8-L8 -> -470.5 | O8: =K8-M8 -> -9267.15 | P8: =20000+O8 -> 10732.85 | Q8: 180 | R8: 18 | S8: 022_02 敬亭治疗成功（银钱+1000）
A9: 1 | B9: 小满 | C9: 3 | D9: 500 | E9: 150 | F9: =IF(C9>=1,VLOOKUP(R8+MAX(0,R9-R8-C9)+0,药材收益口径!$H$2:$I$222,2,FALSE),0)+IF(C9>=2,VLOOKUP(R8+MAX(0,R9-R8-C9)+1,药材收益口径!$H$2:$I$222,2,FALSE),0)+IF(C9>=3,VLOOKUP(R8+MAX(0,R9-R8-C9)+2,药材收益口径!$H$2:$I$222,2,FALSE),0)+IF(C9>=4,VLOOKUP(R8+MAX(0,R9-R8-C9)+3,药材收益口径!$H$2:$I$222,2,FALSE),0) -> 178.88333 | G9: 345.6 | H9: 0 | I9: 0 | J9: =SUM(D9:I9) -> 1174.4833 | K9: =K8+J9 -> 8586.5333 | L9: 3676.4 | M9: =M8+L9 -> 20355.6 | N9: =J9-L9 -> -2501.9167 | O9: =K9-M9 -> -11769.067 | P9: =20000+O9 -> 8230.9333 | Q9: 210 | R9: 21
A10: 1 | B10: 芒种 | C10: 3 | D10: 500 | E10: 150 | F10: =IF(C10>=1,VLOOKUP(R9+MAX(0,R10-R9-C10)+0,药材收益口径!$H$2:$I$222,2,FALSE),0)+IF(C10>=2,VLOOKUP(R9+MAX(0,R10-R9-C10)+1,药材收益口径!$H$2:$I$222,2,FALSE),0)+IF(C10>=3,VLOOKUP(R9+MAX(0,R10-R9-C10)+2,药材收益口径!$H$2:$I$222,2,FALSE),0)+IF(C10>=4,VLOOKUP(R9+MAX(0,R10-R9-C10)+3,药材收益口径!$H$2:$I$222,2,FALSE),0) -> 183.5625 | G10: 345.6 | H10: 0 | I10: 0 | J10: =SUM(D10:I10) -> 1179.1625 | K10: =K9+J10 -> 9765.6958 | L10: 2450 | M10: =M9+L10 -> 22805.6 | N10: =J10-L10 -> -1270.8375 | O10: =K10-M10 -> -13039.904 | P10: =20000+O10 -> 6960.0958 | Q10: 240 | R10: 24
A11: 1 | B11: 夏至 | C11: 3 | D11: 500 | E11: 150 | F11: =IF(C11>=1,VLOOKUP(R10+MAX(0,R11-R10-C11)+0,药材收益口径!$H$2:$I$222,2,FALSE),0)+IF(C11>=2,VLOOKUP(R10+MAX(0,R11-R10-C11)+1,药材收益口径!$H$2:$I$222,2,FALSE),0)+IF(C11>=3,VLOOKUP(R10+MAX(0,R11-R10-C11)+2,药材收益口径!$H$2:$I$222,2,FALSE),0)+IF(C11>=4,VLOOKUP(R10+MAX(0,R11-R10-C11)+3,药材收益口径!$H$2:$I$222,2,FALSE),0) -> 315.5322 | G11: 345.6 | H11: 0 | I11: 0 | J11: =SUM(D11:I11) -> 1311.1322 | K11: =K10+J11 -> 11076.828 | L11: 3676.4 | M11: =M10+L11 -> 26482 | N11: =J11-L11 -> -2365.2678 | O11: =K11-M11 -> -15405.172 | P11: =20000+O11 -> 4594.828 | Q11: 270 | R11: 27
A12: 1 | B12: 小暑 | C12: 3 | D12: 500 | E12: 150 | F12: =IF(C12>=1,VLOOKUP(R11+MAX(0,R12-R11-C12)+0,药材收益口径!$H$2:$I$222,2,FALSE),0)+IF(C12>=2,VLOOKUP(R11+MAX(0,R12-R11-C12)+1,药材收益口径!$H$2:$I$222,2,FALSE),0)+IF(C12>=3,VLOOKUP(R11+MAX(0,R12-R11-C12)+2,药材收益口径!$H$2:$I$222,2,FALSE),0)+IF(C12>=4,VLOOKUP(R11+MAX(0,R12-R11-C12)+3,药材收益口径!$H$2:$I$222,2,FALSE),0) -> 332.5979 | G12: 345.6 | H12: 0 | I12: 0 | J12: =SUM(D12:I12) -> 1328.1979 | K12: =K11+J12 -> 12405.026 | L12: 2450 | M12: =M11+L12 -> 28932 | N12: =J12-L12 -> -1121.8021 | O12: =K12-M12 -> -16526.974 | P12: =20000+O12 -> 3473.0259 | Q12: 300 | R12: 30
A13: 1 | B13: 大暑 | C13: 3 | D13: 500 | E13: 450 | F13: =IF(C13>=1,VLOOKUP(R12+MAX(0,R13-R12-C13)+0,药材收益口径!$H$2:$I$222,2,FALSE),0)+IF(C13>=2,VLOOKUP(R12+MAX(0,R13-R12-C13)+1,药材收益口径!$H$2:$I$222,2,FALSE),0)+IF(C13>=3,VLOOKUP(R12+MAX(0,R13-R12-C13)+2,药材收益口径!$H$2:$I$222,2,FALSE),0)+IF(C13>=4,VLOOKUP(R12+MAX(0,R13-R12-C13)+3,药材收益口径!$H$2:$I$222,2,FALSE),0) -> 323.19231 | G13: 345.6 | H13: 5000 | I13: 0 | J13: =SUM(D13:I13) -> 6618.7923 | K13: =K12+J13 -> 19023.818 | L13: 3276.4 | M13: =M12+L13 -> 32208.4 | N13: =J13-L13 -> 3342.3923 | O13: =K13-M13 -> -13184.582 | P13: =20000+O13 -> 6815.4182 | Q13: 330 | R13: 33
A14: 1 | B14: 立秋 | C14: 3 | D14: 500 | E14: 600 | F14: =IF(C14>=1,VLOOKUP(R13+MAX(0,R14-R13-C14)+0,药材收益口径!$H$2:$I$222,2,FALSE),0)+IF(C14>=2,VLOOKUP(R13+MAX(0,R14-R13-C14)+1,药材收益口径!$H$2:$I$222,2,FALSE),0)+IF(C14>=3,VLOOKUP(R13+MAX(0,R14-R13-C14)+2,药材收益口径!$H$2:$I$222,2,FALSE),0)+IF(C14>=4,VLOOKUP(R13+MAX(0,R14-R13-C14)+3,药材收益口径!$H$2:$I$222,2,FALSE),0) -> 316.6 | G14: 345.6 | H14: 0 | I14: 0 | J14: =SUM(D14:I14) -> 1762.2 | K14: =K13+J14 -> 20786.018 | L14: 2650 | M14: =M13+L14 -> 34858.4 | N14: =J14-L14 -> -887.8 | O14: =K14-M14 -> -14072.382 | P14: =20000+O14 -> 5927.6182 | Q14: 360 | R14: 36
A15: 1 | B15: 处暑 | C15: 3 | D15: 500 | E15: 600 | F15: =IF(C15>=1,VLOOKUP(R14+MAX(0,R15-R14-C15)+0,药材收益口径!$H$2:$I$222,2,FALSE),0)+IF(C15>=2,VLOOKUP(R14+MAX(0,R15-R14-C15)+1,药材收益口径!$H$2:$I$222,2,FALSE),0)+IF(C15>=3,VLOOKUP(R14+MAX(0,R15-R14-C15)+2,药材收益口径!$H$2:$I$222,2,FALSE),0)+IF(C15>=4,VLOOKUP(R14+MAX(0,R15-R14-C15)+3,药材收益口径!$H$2:$I$222,2,FALSE),0) -> 313.90625 | G15: 345.6 | H15: 0 | I15: 0 | J15: =SUM(D15:I15) -> 1759.5062 | K15: =K14+J15 -> 22545.524 | L15: 4776.4 | M15: =M14+L15 -> 39634.8 | N15: =J15-L15 -> -3016.8937 | O15: =K15-M15 -> -17089.276 | P15: =20000+O15 -> 2910.7245 | Q15: 390 | R15: 39
A16: 1 | B16: 白露 | C16: 3 | D16: 500 | E16: 600 | F16: =IF(C16>=1,VLOOKUP(R15+MAX(0,R16-R15-C16)+0,药材收益口径!$H$2:$I$222,2,FALSE),0)+IF(C16>=2,VLOOKUP(R15+MAX(0,R16-R15-C16)+1,药材收益口径!$H$2:$I$222,2,FALSE),0)+IF(C16>=3,VLOOKUP(R15+MAX(0,R16-R15-C16)+2,药材收益口径!$H$2:$I$222,2,FALSE),0)+IF(C16>=4,VLOOKUP(R15+MAX(0,R16-R15-C16)+3,药材收益口径!$H$2:$I$222,2,FALSE),0) -> 318.44444 | G16: 345.6 | H16: 0 | I16: 0 | J16: =SUM(D16:I16) -> 1764.0444 | K16: =K15+J16 -> 24309.569 | L16: 1550 | M16: =M15+L16 -> 41184.8 | N16: =J16-L16 -> 214.04444 | O16: =K16-M16 -> -16875.231 | P16: =20000+O16 -> 3124.7689 | Q16: 420 | R16: 42
A17: 1 | B17: 秋分 | C17: 3 | D17: 500 | E17: 600 | F17: =IF(C17>=1,VLOOKUP(R16+MAX(0,R17-R16-C17)+0,药材收益口径!$H$2:$I$222,2,FALSE),0)+IF(C17>=2,VLOOKUP(R16+MAX(0,R17-R16-C17)+1,药材收益口径!$H$2:$I$222,2,FALSE),0)+IF(C17>=3,VLOOKUP(R16+MAX(0,R17-R16-C17)+2,药材收益口径!$H$2:$I$222,2,FALSE),0)+IF(C17>=4,VLOOKUP(R16+MAX(0,R17-R16-C17)+3,药材收益口径!$H$2:$I$222,2,FALSE),0) -> 319.91813 | G17: 345.6 | H17: 0 | I17: 1000 | J17: =SUM(D17:I17) -> 2765.5181 | K17: =K16+J17 -> 27075.087 | L17: 3376.4 | M17: =M16+L17 -> 44561.2 | N17: =J17-L17 -> -610.88187 | O17: =K17-M17 -> -17486.113 | P17: =20000+O17 -> 2513.8871 | Q17: 450 | R17: 45 | S17: 023_02 谢飞燕肺气虚（银钱+1000）
A18: 1 | B18: 寒露 | C18: 3 | D18: 500 | E18: 600 | F18: =IF(C18>=1,VLOOKUP(R17+MAX(0,R18-R17-C18)+0,药材收益口径!$H$2:$I$222,2,FALSE),0)+IF(C18>=2,VLOOKUP(R17+MAX(0,R18-R17-C18)+1,药材收益口径!$H$2:$I$222,2,FALSE),0)+IF(C18>=3,VLOOKUP(R17+MAX(0,R18-R17-C18)+2,药材收益口径!$H$2:$I$222,2,FALSE),0)+IF(C18>=4,VLOOKUP(R17+MAX(0,R18-R17-C18)+3,药材收益口径!$H$2:$I$222,2,FALSE),0) -> 314.92105 | G18: 345.6 | H18: 0 | I18: 1000 | J18: =SUM(D18:I18) -> 2760.5211 | K18: =K17+J18 -> 29835.608 | L18: 1550 | M18: =M17+L18 -> 46111.2 | N18: =J18-L18 -> 1210.5211 | O18: =K18-M18 -> -16275.592 | P18: =20000+O18 -> 3724.4081 | Q18: 480 | R18: 48 | S18: 024_02 谢飞燕肺阴虚（银钱+1000）
A19: 1 | B19: 霜降 | C19: 3 | D19: 500 | E19: 600 | F19: =IF(C19>=1,VLOOKUP(R18+MAX(0,R19-R18-C19)+0,药材收益口径!$H$2:$I$222,2,FALSE),0)+IF(C19>=2,VLOOKUP(R18+MAX(0,R19-R18-C19)+1,药材收益口径!$H$2:$I$222,2,FALSE),0)+IF(C19>=3,VLOOKUP(R18+MAX(0,R19-R18-C19)+2,药材收益口径!$H$2:$I$222,2,FALSE),0)+IF(C19>=4,VLOOKUP(R18+MAX(0,R19-R18-C19)+3,药材收益口径!$H$2:$I$222,2,FALSE),0) -> 364.29535 | G19: 345.6 | H19: 15000 | I19: 0 | J19: =SUM(D19:I19) -> 16809.895 | K19: =K18+J19 -> 46645.503 | L19: 4276.4 | M19: =M18+L19 -> 50387.6 | N19: =J19-L19 -> 12533.495 | O19: =K19-M19 -> -3742.0965 | P19: =20000+O19 -> 16257.903 | Q19: 510 | R19: 51
A20: 1 | B20: 立冬 | C20: 3 | D20: 500 | E20: 600 | F20: =IF(C20>=1,VLOOKUP(R19+MAX(0,R20-R19-C20)+0,药材收益口径!$H$2:$I$222,2,FALSE),0)+IF(C20>=2,VLOOKUP(R19+MAX(0,R20-R19-C20)+1,药材收益口径!$H$2:$I$222,2,FALSE),0)+IF(C20>=3,VLOOKUP(R19+MAX(0,R20-R19-C20)+2,药材收益口径!$H$2:$I$222,2,FALSE),0)+IF(C20>=4,VLOOKUP(R19+MAX(0,R20-R19-C20)+3,药材收益口径!$H$2:$I$222,2,FALSE),0) -> 354.97925 | G20: 345.6 | H20: 0 | I20: 0 | J20: =SUM(D20:I20) -> 1800.5792 | K20: =K19+J20 -> 48446.083 | L20: 4750 | M20: =M19+L20 -> 55137.6 | N20: =J20-L20 -> -2949.4208 | O20: =K20-M20 -> -6691.5173 | P20: =20000+O20 -> 13308.483 | Q20: 540 | R20: 54
A21: 1 | B21: 小雪 | C21: 3 | D21: 500 | E21: 600 | F21: =IF(C21>=1,VLOOKUP(R20+MAX(0,R21-R20-C21)+0,药材收益口径!$H$2:$I$222,2,FALSE),0)+IF(C21>=2,VLOOKUP(R20+MAX(0,R21-R20-C21)+1,药材收益口径!$H$2:$I$222,2,FALSE),0)+IF(C21>=3,VLOOKUP(R20+MAX(0,R21-R20-C21)+2,药材收益口径!$H$2:$I$222,2,FALSE),0)+IF(C21>=4,VLOOKUP(R20+MAX(0,R21-R20-C21)+3,药材收益口径!$H$2:$I$222,2,FALSE),0) -> 352.74471 | G21: 345.6 | H21: 0 | I21: 1000 | J21: =SUM(D21:I21) -> 2798.3447 | K21: =K20+J21 -> 51244.427 | L21: 2776.4 | M21: =M20+L21 -> 57914 | N21: =J21-L21 -> 21.944709 | O21: =K21-M21 -> -6669.5726 | P21: =20000+O21 -> 13330.427 | Q21: 1570 | R21: 64 | S21: 024_04 王百堂来访（心得+7）；005_02 治愈世子（银钱+1000，名望+1000）
A22: 1 | B22: 大雪 | C22: 3 | D22: 500 | E22: 1500 | F22: =IF(C22>=1,VLOOKUP(R21+MAX(0,R22-R21-C22)+0,药材收益口径!$H$2:$I$222,2,FALSE),0)+IF(C22>=2,VLOOKUP(R21+MAX(0,R22-R21-C22)+1,药材收益口径!$H$2:$I$222,2,FALSE),0)+IF(C22>=3,VLOOKUP(R21+MAX(0,R22-R21-C22)+2,药材收益口径!$H$2:$I$222,2,FALSE),0)+IF(C22>=4,VLOOKUP(R21+MAX(0,R22-R21-C22)+3,药材收益口径!$H$2:$I$222,2,FALSE),0) -> 351.58929 | G22: 345.6 | H22: 0 | I22: 0 | J22: =SUM(D22:I22) -> 2697.1893 | K22: =K21+J22 -> 53941.617 | L22: 1550 | M22: =M21+L22 -> 59464 | N22: =J22-L22 -> 1147.1893 | O22: =K22-M22 -> -5522.3833 | P22: =20000+O22 -> 14477.617 | Q22: 1600 | R22: 67
A23: 1 | B23: 冬至 | C23: 3 | D23: 500 | E23: 1500 | F23: =IF(C23>=1,VLOOKUP(R22+MAX(0,R23-R22-C23)+0,药材收益口径!$H$2:$I$222,2,FALSE),0)+IF(C23>=2,VLOOKUP(R22+MAX(0,R23-R22-C23)+1,药材收益口径!$H$2:$I$222,2,FALSE),0)+IF(C23>=3,VLOOKUP(R22+MAX(0,R23-R22-C23)+2,药材收益口径!$H$2:$I$222,2,FALSE),0)+IF(C23>=4,VLOOKUP(R22+MAX(0,R23-R22-C23)+3,药材收益口径!$H$2:$I$222,2,FALSE),0) -> 372.87931 | G23: 345.6 | H23: 0 | I23: 0 | J23: =SUM(D23:I23) -> 2718.4793 | K23: =K22+J23 -> 56660.096 | L23: 2776.4 | M23: =M22+L23 -> 62240.4 | N23: =J23-L23 -> -57.92069 | O23: =K23-M23 -> -5580.304 | P23: =20000+O23 -> 14419.696 | Q23: 1630 | R23: 70
A24: 1 | B24: 小寒 | C24: 3 | D24: 500 | E24: 1500 | F24: =IF(C24>=1,VLOOKUP(R23+MAX(0,R24-R23-C24)+0,药材收益口径!$H$2:$I$222,2,FALSE),0)+IF(C24>=2,VLOOKUP(R23+MAX(0,R24-R23-C24)+1,药材收益口径!$H$2:$I$222,2,FALSE),0)+IF(C24>=3,VLOOKUP(R23+MAX(0,R24-R23-C24)+2,药材收益口径!$H$2:$I$222,2,FALSE),0)+IF(C24>=4,VLOOKUP(R23+MAX(0,R24-R23-C24)+3,药材收益口径!$H$2:$I$222,2,FALSE),0) -> 370.73137 | G24: 345.6 | H24: 0 | I24: 0 | J24: =SUM(D24:I24) -> 2716.3314 | K24: =K23+J24 -> 59376.427 | L24: 1550 | M24: =M23+L24 -> 63790.4 | N24: =J24-L24 -> 1166.3314 | O24: =K24-M24 -> -4413.9726 | P24: =20000+O24 -> 15586.027 | Q24: 1660 | R24: 73
A25: 1 | B25: 大寒 | C25: 3 | D25: 500 | E25: 1500 | F25: =IF(C25>=1,VLOOKUP(R24+MAX(0,R25-R24-C25)+0,药材收益口径!$H$2:$I$222,2,FALSE),0)+IF(C25>=2,VLOOKUP(R24+MAX(0,R25-R24-C25)+1,药材收益口径!$H$2:$I$222,2,FALSE),0)+IF(C25>=3,VLOOKUP(R24+MAX(0,R25-R24-C25)+2,药材收益口径!$H$2:$I$222,2,FALSE),0)+IF(C25>=4,VLOOKUP(R24+MAX(0,R25-R24-C25)+3,药材收益口径!$H$2:$I$222,2,FALSE),0) -> 387.93095 | G25: 345.6 | H25: 0 | I25: 0 | J25: =SUM(D25:I25) -> 2733.5309 | K25: =K24+J25 -> 62109.958 | L25: 3376.4 | M25: =M24+L25 -> 67166.8 | N25: =J25-L25 -> -642.86905 | O25: =K25-M25 -> -5056.8417 | P25: =20000+O25 -> 14943.158 | Q25: 1690 | R25: 76
A26: 2 | B26: 立春 | C26: 3 | D26: 500 | E26: 1500 | F26: =IF(C26>=1,VLOOKUP(R25+MAX(0,R26-R25-C26)+0,药材收益口径!$H$2:$I$222,2,FALSE),0)+IF(C26>=2,VLOOKUP(R25+MAX(0,R26-R25-C26)+1,药材收益口径!$H$2:$I$222,2,FALSE),0)+IF(C26>=3,VLOOKUP(R25+MAX(0,R26-R25-C26)+2,药材收益口径!$H$2:$I$222,2,FALSE),0)+IF(C26>=4,VLOOKUP(R25+MAX(0,R26-R25-C26)+3,药材收益口径!$H$2:$I$222,2,FALSE),0) -> 433.35339 | G26: 345.6 | H26: 0 | I26: 0 | J26: =SUM(D26:I26) -> 2778.9534 | K26: =K25+J26 -> 64888.912 | L26: 2650 | M26: =M25+L26 -> 69816.8 | N26: =J26-L26 -> 128.95339 | O26: =K26-M26 -> -4927.8883 | P26: =20000+O26 -> 15072.112 | Q26: 1720 | R26: 79
A27: 2 | B27: 雨水 | C27: 3 | D27: 500 | E27: 1500 | F27: =IF(C27>=1,VLOOKUP(R26+MAX(0,R27-R26-C27)+0,药材收益口径!$H$2:$I$222,2,FALSE),0)+IF(C27>=2,VLOOKUP(R26+MAX(0,R27-R26-C27)+1,药材收益口径!$H$2:$I$222,2,FALSE),0)+IF(C27>=3,VLOOKUP(R26+MAX(0,R27-R26-C27)+2,药材收益口径!$H$2:$I$222,2,FALSE),0)+IF(C27>=4,VLOOKUP(R26+MAX(0,R27-R26-C27)+3,药材收益口径!$H$2:$I$222,2,FALSE),0) -> 446.26218 | G27: 345.6 | H27: 0 | I27: 0 | J27: =SUM(D27:I27) -> 2791.8622 | K27: =K26+J27 -> 67680.774 | L27: 2776.4 | M27: =M26+L27 -> 72593.2 | N27: =J27-L27 -> 15.462185 | O27: =K27-M27 -> -4912.4261 | P27: =20000+O27 -> 15087.574 | Q27: 1750 | R27: 82
A28: 2 | B28: 惊蛰 | C28: 3 | D28: 500 | E28: 1500 | F28: =IF(C28>=1,VLOOKUP(R27+MAX(0,R28-R27-C28)+0,药材收益口径!$H$2:$I$222,2,FALSE),0)+IF(C28>=2,VLOOKUP(R27+MAX(0,R28-R27-C28)+1,药材收益口径!$H$2:$I$222,2,FALSE),0)+IF(C28>=3,VLOOKUP(R27+MAX(0,R28-R27-C28)+2,药材收益口径!$H$2:$I$222,2,FALSE),0)+IF(C28>=4,VLOOKUP(R27+MAX(0,R28-R27-C28)+3,药材收益口径!$H$2:$I$222,2,FALSE),0) -> 445.75714 | G28: 345.6 | H28: 0 | I28: 0 | J28: =SUM(D28:I28) -> 2791.3571 | K28: =K27+J28 -> 70472.131 | L28: 1550 | M28: =M27+L28 -> 74143.2 | N28: =J28-L28 -> 1241.3571 | O28: =K28-M28 -> -3671.069 | P28: =20000+O28 -> 16328.931 | Q28: 1780 | R28: 85
A29: 2 | B29: 春分 | C29: 3 | D29: 500 | E29: 1500 | F29: =IF(C29>=1,VLOOKUP(R28+MAX(0,R29-R28-C29)+0,药材收益口径!$H$2:$I$222,2,FALSE),0)+IF(C29>=2,VLOOKUP(R28+MAX(0,R29-R28-C29)+1,药材收益口径!$H$2:$I$222,2,FALSE),0)+IF(C29>=3,VLOOKUP(R28+MAX(0,R29-R28-C29)+2,药材收益口径!$H$2:$I$222,2,FALSE),0)+IF(C29>=4,VLOOKUP(R28+MAX(0,R29-R28-C29)+3,药材收益口径!$H$2:$I$222,2,FALSE),0) -> 434.38551 | G29: 345.6 | H29: 0 | I29: 0 | J29: =SUM(D29:I29) -> 2779.9855 | K29: =K28+J29 -> 73252.117 | L29: 3376.4 | M29: =M28+L29 -> 77519.6 | N29: =J29-L29 -> -596.41449 | O29: =K29-M29 -> -4267.4834 | P29: =20000+O29 -> 15732.517 | Q29: 1810 | R29: 88
A30: 2 | B30: 清明 | C30: 3 | D30: 500 | E30: 1500 | F30: =IF(C30>=1,VLOOKUP(R29+MAX(0,R30-R29-C30)+0,药材收益口径!$H$2:$I$222,2,FALSE),0)+IF(C30>=2,VLOOKUP(R29+MAX(0,R30-R29-C30)+1,药材收益口径!$H$2:$I$222,2,FALSE),0)+IF(C30>=3,VLOOKUP(R29+MAX(0,R30-R29-C30)+2,药材收益口径!$H$2:$I$222,2,FALSE),0)+IF(C30>=4,VLOOKUP(R29+MAX(0,R30-R29-C30)+3,药材收益口径!$H$2:$I$222,2,FALSE),0) -> 429.59354 | G30: 345.6 | H30: 0 | I30: 0 | J30: =SUM(D30:I30) -> 2775.1935 | K30: =K29+J30 -> 76027.31 | L30: 3550 | M30: =M29+L30 -> 81069.6 | N30: =J30-L30 -> -774.80646 | O30: =K30-M30 -> -5042.2899 | P30: =20000+O30 -> 14957.71 | Q30: 1840 | R30: 91
A31: 2 | B31: 谷雨 | C31: 3 | D31: 500 | E31: 1500 | F31: =IF(C31>=1,VLOOKUP(R30+MAX(0,R31-R30-C31)+0,药材收益口径!$H$2:$I$222,2,FALSE),0)+IF(C31>=2,VLOOKUP(R30+MAX(0,R31-R30-C31)+1,药材收益口径!$H$2:$I$222,2,FALSE),0)+IF(C31>=3,VLOOKUP(R30+MAX(0,R31-R30-C31)+2,药材收益口径!$H$2:$I$222,2,FALSE),0)+IF(C31>=4,VLOOKUP(R30+MAX(0,R31-R30-C31)+3,药材收益口径!$H$2:$I$222,2,FALSE),0) -> 433.33354 | G31: 345.6 | H31: 0 | I31: 0 | J31: =SUM(D31:I31) -> 2778.9335 | K31: =K30+J31 -> 78806.244 | L31: 2776.4 | M31: =M30+L31 -> 83846 | N31: =J31-L31 -> 2.5335444 | O31: =K31-M31 -> -5039.7564 | P31: =20000+O31 -> 14960.244 | Q31: 1870 | R31: 94
A32: 2 | B32: 立夏 | C32: 3 | D32: 500 | E32: 1500 | F32: =IF(C32>=1,VLOOKUP(R31+MAX(0,R32-R31-C32)+0,药材收益口径!$H$2:$I$222,2,FALSE),0)+IF(C32>=2,VLOOKUP(R31+MAX(0,R32-R31-C32)+1,药材收益口径!$H$2:$I$222,2,FALSE),0)+IF(C32>=3,VLOOKUP(R31+MAX(0,R32-R31-C32)+2,药材收益口径!$H$2:$I$222,2,FALSE),0)+IF(C32>=4,VLOOKUP(R31+MAX(0,R32-R31-C32)+3,药材收益口径!$H$2:$I$222,2,FALSE),0) -> 432.48918 | G32: 345.6 | H32: 0 | I32: 0 | J32: =SUM(D32:I32) -> 2778.0892 | K32: =K31+J32 -> 81584.333 | L32: 2650 | M32: =M31+L32 -> 86496 | N32: =J32-L32 -> 128.08918 | O32: =K32-M32 -> -4911.6672 | P32: =20000+O32 -> 15088.333 | Q32: 1900 | R32: 97
A33: 2 | B33: 小满 | C33: 3 | D33: 500 | E33: 1500 | F33: =IF(C33>=1,VLOOKUP(R32+MAX(0,R33-R32-C33)+0,药材收益口径!$H$2:$I$222,2,FALSE),0)+IF(C33>=2,VLOOKUP(R32+MAX(0,R33-R32-C33)+1,药材收益口径!$H$2:$I$222,2,FALSE),0)+IF(C33>=3,VLOOKUP(R32+MAX(0,R33-R32-C33)+2,药材收益口径!$H$2:$I$222,2,FALSE),0)+IF(C33>=4,VLOOKUP(R32+MAX(0,R33-R32-C33)+3,药材收益口径!$H$2:$I$222,2,FALSE),0) -> 439.12753 | G33: 345.6 | H33: 0 | I33: 0 | J33: =SUM(D33:I33) -> 2784.7275 | K33: =K32+J33 -> 84369.06 | L33: 3676.4 | M33: =M32+L33 -> 90172.4 | N33: =J33-L33 -> -891.67247 | O33: =K33-M33 -> -5803.3397 | P33: =20000+O33 -> 14196.66 | Q33: 1930 | R33: 100
A34: 2 | B34: 芒种 | C34: 3 | D34: 500 | E34: 1500 | F34: =IF(C34>=1,VLOOKUP(R33+MAX(0,R34-R33-C34)+0,药材收益口径!$H$2:$I$222,2,FALSE),0)+IF(C34>=2,VLOOKUP(R33+MAX(0,R34-R33-C34)+1,药材收益口径!$H$2:$I$222,2,FALSE),0)+IF(C34>=3,VLOOKUP(R33+MAX(0,R34-R33-C34)+2,药材收益口径!$H$2:$I$222,2,FALSE),0)+IF(C34>=4,VLOOKUP(R33+MAX(0,R34-R33-C34)+3,药材收益口径!$H$2:$I$222,2,FALSE),0) -> 443.83333 | G34: 345.6 | H34: 0 | I34: 2000 | J34: =SUM(D34:I34) -> 4789.4333 | K34: =K33+J34 -> 89158.494 | L34: 2450 | M34: =M33+L34 -> 92622.4 | N34: =J34-L34 -> 2339.4333 | O34: =K34-M34 -> -3463.9063 | P34: =20000+O34 -> 16536.094 | Q34: 1960 | R34: 103 | S34: 025_02 和尚肾精不足（银钱+2000）
A35: 2 | B35: 夏至 | C35: 3 | D35: 500 | E35: 1500 | F35: =IF(C35>=1,VLOOKUP(R34+MAX(0,R35-R34-C35)+0,药材收益口径!$H$2:$I$222,2,FALSE),0)+IF(C35>=2,VLOOKUP(R34+MAX(0,R35-R34-C35)+1,药材收益口径!$H$2:$I$222,2,FALSE),0)+IF(C35>=3,VLOOKUP(R34+MAX(0,R35-R34-C35)+2,药材收益口径!$H$2:$I$222,2,FALSE),0)+IF(C35>=4,VLOOKUP(R34+MAX(0,R35-R34-C35)+3,药材收益口径!$H$2:$I$222,2,FALSE),0) -> 449.63145 | G35: 345.6 | H35: 0 | I35: 0 | J35: =SUM(D35:I35) -> 2795.2315 | K35: =K34+J35 -> 91953.725 | L35: 3676.4 | M35: =M34+L35 -> 96298.8 | N35: =J35-L35 -> -881.16855 | O35: =K35-M35 -> -4345.0749 | P35: =20000+O35 -> 15654.925 | Q35: 1990 | R35: 106
A36: 2 | B36: 小暑 | C36: 3 | D36: 500 | E36: 2000 | F36: =IF(C36>=1,VLOOKUP(R35+MAX(0,R36-R35-C36)+0,药材收益口径!$H$2:$I$222,2,FALSE),0)+IF(C36>=2,VLOOKUP(R35+MAX(0,R36-R35-C36)+1,药材收益口径!$H$2:$I$222,2,FALSE),0)+IF(C36>=3,VLOOKUP(R35+MAX(0,R36-R35-C36)+2,药材收益口径!$H$2:$I$222,2,FALSE),0)+IF(C36>=4,VLOOKUP(R35+MAX(0,R36-R35-C36)+3,药材收益口径!$H$2:$I$222,2,FALSE),0) -> 447.82748 | G36: 345.6 | H36: 0 | I36: 0 | J36: =SUM(D36:I36) -> 3293.4275 | K36: =K35+J36 -> 95247.153 | L36: 2450 | M36: =M35+L36 -> 98748.8 | N36: =J36-L36 -> 843.42748 | O36: =K36-M36 -> -3501.6474 | P36: =20000+O36 -> 16498.353 | Q36: 2020 | R36: 109
A37: 2 | B37: 大暑 | C37: 3 | D37: 500 | E37: 3000 | F37: =IF(C37>=1,VLOOKUP(R36+MAX(0,R37-R36-C37)+0,药材收益口径!$H$2:$I$222,2,FALSE),0)+IF(C37>=2,VLOOKUP(R36+MAX(0,R37-R36-C37)+1,药材收益口径!$H$2:$I$222,2,FALSE),0)+IF(C37>=3,VLOOKUP(R36+MAX(0,R37-R36-C37)+2,药材收益口径!$H$2:$I$222,2,FALSE),0)+IF(C37>=4,VLOOKUP(R36+MAX(0,R37-R36-C37)+3,药材收益口径!$H$2:$I$222,2,FALSE),0) -> 447.45709 | G37: 345.6 | H37: 5000 | I37: 0 | J37: =SUM(D37:I37) -> 9293.0571 | K37: =K36+J37 -> 104540.21 | L37: 3276.4 | M37: =M36+L37 -> 102025.2 | N37: =J37-L37 -> 6016.6571 | O37: =K37-M37 -> 2515.0097 | P37: =20000+O37 -> 22515.01 | Q37: 2050 | R37: 112
A38: 2 | B38: 立秋 | C38: 3 | D38: 500 | E38: 3000 | F38: =IF(C38>=1,VLOOKUP(R37+MAX(0,R38-R37-C38)+0,药材收益口径!$H$2:$I$222,2,FALSE),0)+IF(C38>=2,VLOOKUP(R37+MAX(0,R38-R37-C38)+1,药材收益口径!$H$2:$I$222,2,FALSE),0)+IF(C38>=3,VLOOKUP(R37+MAX(0,R38-R37-C38)+2,药材收益口径!$H$2:$I$222,2,FALSE),0)+IF(C38>=4,VLOOKUP(R37+MAX(0,R38-R37-C38)+3,药材收益口径!$H$2:$I$222,2,FALSE),0) -> 447.45709 | G38: 345.6 | H38: 0 | I38: 0 | J38: =SUM(D38:I38) -> 4293.0571 | K38: =K37+J38 -> 108833.27 | L38: 2650 | M38: =M37+L38 -> 104675.2 | N38: =J38-L38 -> 1643.0571 | O38: =K38-M38 -> 4158.0668 | P38: =20000+O38 -> 24158.067 | Q38: 2080 | R38: 115
A39: 2 | B39: 处暑 | C39: 3 | D39: 500 | E39: 3000 | F39: =IF(C39>=1,VLOOKUP(R38+MAX(0,R39-R38-C39)+0,药材收益口径!$H$2:$I$222,2,FALSE),0)+IF(C39>=2,VLOOKUP(R38+MAX(0,R39-R38-C39)+1,药材收益口径!$H$2:$I$222,2,FALSE),0)+IF(C39>=3,VLOOKUP(R38+MAX(0,R39-R38-C39)+2,药材收益口径!$H$2:$I$222,2,FALSE),0)+IF(C39>=4,VLOOKUP(R38+MAX(0,R39-R38-C39)+3,药材收益口径!$H$2:$I$222,2,FALSE),0) -> 447.45709 | G39: 345.6 | H39: 0 | I39: 0 | J39: =SUM(D39:I39) -> 4293.0571 | K39: =K38+J39 -> 113126.32 | L39: 4776.4 | M39: =M38+L39 -> 109451.6 | N39: =J39-L39 -> -483.34291 | O39: =K39-M39 -> 3674.7239 | P39: =20000+O39 -> 23674.724 | Q39: 2110 | R39: 118
A40: 2 | B40: 白露 | C40: 3 | D40: 500 | E40: 3000 | F40: =IF(C40>=1,VLOOKUP(R39+MAX(0,R40-R39-C40)+0,药材收益口径!$H$2:$I$222,2,FALSE),0)+IF(C40>=2,VLOOKUP(R39+MAX(0,R40-R39-C40)+1,药材收益口径!$H$2:$I$222,2,FALSE),0)+IF(C40>=3,VLOOKUP(R39+MAX(0,R40-R39-C40)+2,药材收益口径!$H$2:$I$222,2,FALSE),0)+IF(C40>=4,VLOOKUP(R39+MAX(0,R40-R39-C40)+3,药材收益口径!$H$2:$I$222,2,FALSE),0) -> 447.45709 | G40: 345.6 | H40: 0 | I40: 0 | J40: =SUM(D40:I40) -> 4293.0571 | K40: =K39+J40 -> 117419.38 | L40: 1550 | M40: =M39+L40 -> 111001.6 | N40: =J40-L40 -> 2743.0571 | O40: =K40-M40 -> 6417.781 | P40: =20000+O40 -> 26417.781 | Q40: 2140 | R40: 121
...

Sheet 困难
A1: 年份 | B1: 节气 | C1: 妙手回春次数 | D1: 李言闻收入 | E1: 诊费预期 | F1: 药材净收入预期 | G1: 谢仪预期 | H1: 田租 | I1: 剧情银钱奖励 | J1: 预期收入 | K1: 累计预期收入 | L1: 预期支出 | M1: 累计预期支出 | N1: 本节气收支差 | O1: 累计收支差 | P1: 含初始资金余额 | Q1: 节气末名望 | R1: 节气末心得 | S1: 剧情备注
A2: 1 | B2: 立春 | C2: 0 | D2: 0 | E2: 0 | F2: =IF(C2>=1,VLOOKUP(0+MAX(0,R2-0-C2)+0,药材收益口径!$H$2:$I$222,2,FALSE),0)+IF(C2>=2,VLOOKUP(0+MAX(0,R2-0-C2)+1,药材收益口径!$H$2:$I$222,2,FALSE),0)+IF(C2>=3,VLOOKUP(0+MAX(0,R2-0-C2)+2,药材收益口径!$H$2:$I$222,2,FALSE),0)+IF(C2>=4,VLOOKUP(0+MAX(0,R2-0-C2)+3,药材收益口径!$H$2:$I$222,2,FALSE),0) -> 0 | G2: 0 | H2: 0 | I2: 0 | J2: =SUM(D2:I2) -> 0 | K2: =J2 -> 0 | L2: =K2 -> 0 | M2: =L2 -> 0 | N2: =J2-L2 -> 0 | O2: =K2-M2 -> 0 | P2: =20000+O2 -> 20000 | Q2: 0 | R2: 0
A3: 1 | B3: 雨水 | C3: 4 | D3: 0 | E3: 80 | F3: =IF(C3>=1,VLOOKUP(R2+MAX(0,R3-R2-C3)+0,药材收益口径!$H$2:$I$222,2,FALSE),0)+IF(C3>=2,VLOOKUP(R2+MAX(0,R3-R2-C3)+1,药材收益口径!$H$2:$I$222,2,FALSE),0)+IF(C3>=3,VLOOKUP(R2+MAX(0,R3-R2-C3)+2,药材收益口径!$H$2:$I$222,2,FALSE),0)+IF(C3>=4,VLOOKUP(R2+MAX(0,R3-R2-C3)+3,药材收益口径!$H$2:$I$222,2,FALSE),0) -> 78.666667 | G3: 460.8 | H3: 0 | I3: 0 | J3: =SUM(D3:I3) -> 619.46667 | K3: =K2+J3 -> 619.46667 | L3: 2776.4 | M3: =M2+L3 -> 2776.4 | N3: =J3-L3 -> -2156.9333 | O3: =K3-M3 -> -2156.9333 | P3: =20000+O3 -> 17843.067 | Q3: 40 | R3: 4
A4: 1 | B4: 惊蛰 | C4: 4 | D4: 0 | E4: 80 | F4: =IF(C4>=1,VLOOKUP(R3+MAX(0,R4-R3-C4)+0,药材收益口径!$H$2:$I$222,2,FALSE),0)+IF(C4>=2,VLOOKUP(R3+MAX(0,R4-R3-C4)+1,药材收益口径!$H$2:$I$222,2,FALSE),0)+IF(C4>=3,VLOOKUP(R3+MAX(0,R4-R3-C4)+2,药材收益口径!$H$2:$I$222,2,FALSE),0)+IF(C4>=4,VLOOKUP(R3+MAX(0,R4-R3-C4)+3,药材收益口径!$H$2:$I$222,2,FALSE),0) -> 78.666667 | G4: 460.8 | H4: 0 | I4: 0 | J4: =SUM(D4:I4) -> 619.46667 | K4: =K3+J4 -> 1238.9333 | L4: 1550 | M4: =M3+L4 -> 4326.4 | N4: =J4-L4 -> -930.53333 | O4: =K4-M4 -> -3087.4667 | P4: =20000+O4 -> 16912.533 | Q4: 80 | R4: 8
A5: 1 | B5: 春分 | C5: 4 | D5: 0 | E5: 110 | F5: =IF(C5>=1,VLOOKUP(R4+MAX(0,R5-R4-C5)+0,药材收益口径!$H$2:$I$222,2,FALSE),0)+IF(C5>=2,VLOOKUP(R4+MAX(0,R5-R4-C5)+1,药材收益口径!$H$2:$I$222,2,FALSE),0)+IF(C5>=3,VLOOKUP(R4+MAX(0,R5-R4-C5)+2,药材收益口径!$H$2:$I$222,2,FALSE),0)+IF(C5>=4,VLOOKUP(R4+MAX(0,R5-R4-C5)+3,药材收益口径!$H$2:$I$222,2,FALSE),0) -> 227.41667 | G5: 460.8 | H5: 0 | I5: 0 | J5: =SUM(D5:I5) -> 798.21667 | K5: =K4+J5 -> 2037.15 | L5: 3376.4 | M5: =M4+L5 -> 7702.8 | N5: =J5-L5 -> -2578.1833 | O5: =K5-M5 -> -5665.65 | P5: =20000+O5 -> 14334.35 | Q5: 120 | R5: 12
A6: 1 | B6: 清明 | C6: 4 | D6: 0 | E6: 200 | F6: =IF(C6>=1,VLOOKUP(R5+MAX(0,R6-R5-C6)+0,药材收益口径!$H$2:$I$222,2,FALSE),0)+IF(C6>=2,VLOOKUP(R5+MAX(0,R6-R5-C6)+1,药材收益口径!$H$2:$I$222,2,FALSE),0)+IF(C6>=3,VLOOKUP(R5+MAX(0,R6-R5-C6)+2,药材收益口径!$H$2:$I$222,2,FALSE),0)+IF(C6>=4,VLOOKUP(R5+MAX(0,R6-R5-C6)+3,药材收益口径!$H$2:$I$222,2,FALSE),0) -> 261.1 | G6: 460.8 | H6: 0 | I6: 0 | J6: =SUM(D6:I6) -> 921.9 | K6: =K5+J6 -> 2959.05 | L6: 3550 | M6: =M5+L6 -> 11252.8 | N6: =J6-L6 -> -2628.1 | O6: =K6-M6 -> -8293.75 | P6: =20000+O6 -> 11706.25 | Q6: 160 | R6: 16
A7: 1 | B7: 谷雨 | C7: 4 | D7: 0 | E7: 200 | F7: =IF(C7>=1,VLOOKUP(R6+MAX(0,R7-R6-C7)+0,药材收益口径!$H$2:$I$222,2,FALSE),0)+IF(C7>=2,VLOOKUP(R6+MAX(0,R7-R6-C7)+1,药材收益口径!$H$2:$I$222,2,FALSE),0)+IF(C7>=3,VLOOKUP(R6+MAX(0,R7-R6-C7)+2,药材收益口径!$H$2:$I$222,2,FALSE),0)+IF(C7>=4,VLOOKUP(R6+MAX(0,R7-R6-C7)+3,药材收益口径!$H$2:$I$222,2,FALSE),0) -> 241.98333 | G7: 460.8 | H7: 0 | I7: 1000 | J7: =SUM(D7:I7) -> 1902.7833 | K7: =K6+J7 -> 4861.8333 | L7: 2776.4 | M7: =M6+L7 -> 14029.2 | N7: =J7-L7 -> -873.61667 | O7: =K7-M7 -> -9167.3667 | P7: =20000+O7 -> 10832.633 | Q7: 200 | R7: 20 | S7: 022_02 敬亭治疗成功（银钱+1000）
A8: 1 | B8: 立夏 | C8: 4 | D8: 0 | E8: 200 | F8: =IF(C8>=1,VLOOKUP(R7+MAX(0,R8-R7-C8)+0,药材收益口径!$H$2:$I$222,2,FALSE),0)+IF(C8>=2,VLOOKUP(R7+MAX(0,R8-R7-C8)+1,药材收益口径!$H$2:$I$222,2,FALSE),0)+IF(C8>=3,VLOOKUP(R7+MAX(0,R8-R7-C8)+2,药材收益口径!$H$2:$I$222,2,FALSE),0)+IF(C8>=4,VLOOKUP(R7+MAX(0,R8-R7-C8)+3,药材收益口径!$H$2:$I$222,2,FALSE),0) -> 243.0625 | G8: 460.8 | H8: 0 | I8: 0 | J8: =SUM(D8:I8) -> 903.8625 | K8: =K7+J8 -> 5765.6958 | L8: 2650 | M8: =M7+L8 -> 16679.2 | N8: =J8-L8 -> -1746.1375 | O8: =K8-M8 -> -10913.504 | P8: =20000+O8 -> 9086.4958 | Q8: 240 | R8: 24
A9: 1 | B9: 小满 | C9: 4 | D9: 0 | E9: 200 | F9: =IF(C9>=1,VLOOKUP(R8+MAX(0,R9-R8-C9)+0,药材收益口径!$H$2:$I$222,2,FALSE),0)+IF(C9>=2,VLOOKUP(R8+MAX(0,R9-R8-C9)+1,药材收益口径!$H$2:$I$222,2,FALSE),0)+IF(C9>=3,VLOOKUP(R8+MAX(0,R9-R8-C9)+2,药材收益口径!$H$2:$I$222,2,FALSE),0)+IF(C9>=4,VLOOKUP(R8+MAX(0,R9-R8-C9)+3,药材收益口径!$H$2:$I$222,2,FALSE),0) -> 432.66856 | G9: 460.8 | H9: 0 | I9: 0 | J9: =SUM(D9:I9) -> 1093.4686 | K9: =K8+J9 -> 6859.1644 | L9: 3676.4 | M9: =M8+L9 -> 20355.6 | N9: =J9-L9 -> -2582.9314 | O9: =K9-M9 -> -13496.436 | P9: =20000+O9 -> 6503.5644 | Q9: 280 | R9: 28
A10: 1 | B10: 芒种 | C10: 4 | D10: 0 | E10: 350 | F10: =IF(C10>=1,VLOOKUP(R9+MAX(0,R10-R9-C10)+0,药材收益口径!$H$2:$I$222,2,FALSE),0)+IF(C10>=2,VLOOKUP(R9+MAX(0,R10-R9-C10)+1,药材收益口径!$H$2:$I$222,2,FALSE),0)+IF(C10>=3,VLOOKUP(R9+MAX(0,R10-R9-C10)+2,药材收益口径!$H$2:$I$222,2,FALSE),0)+IF(C10>=4,VLOOKUP(R9+MAX(0,R10-R9-C10)+3,药材收益口径!$H$2:$I$222,2,FALSE),0) -> 430.92308 | G10: 460.8 | H10: 0 | I10: 0 | J10: =SUM(D10:I10) -> 1241.7231 | K10: =K9+J10 -> 8100.8875 | L10: 2450 | M10: =M9+L10 -> 22805.6 | N10: =J10-L10 -> -1208.2769 | O10: =K10-M10 -> -14704.713 | P10: =20000+O10 -> 5295.2875 | Q10: 320 | R10: 32
A11: 1 | B11: 夏至 | C11: 4 | D11: 0 | E11: 800 | F11: =IF(C11>=1,VLOOKUP(R10+MAX(0,R11-R10-C11)+0,药材收益口径!$H$2:$I$222,2,FALSE),0)+IF(C11>=2,VLOOKUP(R10+MAX(0,R11-R10-C11)+1,药材收益口径!$H$2:$I$222,2,FALSE),0)+IF(C11>=3,VLOOKUP(R10+MAX(0,R11-R10-C11)+2,药材收益口径!$H$2:$I$222,2,FALSE),0)+IF(C11>=4,VLOOKUP(R10+MAX(0,R11-R10-C11)+3,药材收益口径!$H$2:$I$222,2,FALSE),0) -> 424.33077 | G11: 460.8 | H11: 0 | I11: 0 | J11: =SUM(D11:I11) -> 1685.1308 | K11: =K10+J11 -> 9786.0182 | L11: 3676.4 | M11: =M10+L11 -> 26482 | N11: =J11-L11 -> -1991.2692 | O11: =K11-M11 -> -16695.982 | P11: =20000+O11 -> 3304.0182 | Q11: 360 | R11: 36
A12: 1 | B12: 小暑 | C12: 4 | D12: 0 | E12: 800 | F12: =IF(C12>=1,VLOOKUP(R11+MAX(0,R12-R11-C12)+0,药材收益口径!$H$2:$I$222,2,FALSE),0)+IF(C12>=2,VLOOKUP(R11+MAX(0,R12-R11-C12)+1,药材收益口径!$H$2:$I$222,2,FALSE),0)+IF(C12>=3,VLOOKUP(R11+MAX(0,R12-R11-C12)+2,药材收益口径!$H$2:$I$222,2,FALSE),0)+IF(C12>=4,VLOOKUP(R11+MAX(0,R12-R11-C12)+3,药材收益口径!$H$2:$I$222,2,FALSE),0) -> 417.40625 | G12: 460.8 | H12: 0 | I12: 0 | J12: =SUM(D12:I12) -> 1678.2062 | K12: =K11+J12 -> 11464.224 | L12: 2450 | M12: =M11+L12 -> 28932 | N12: =J12-L12 -> -771.79375 | O12: =K12-M12 -> -17467.776 | P12: =20000+O12 -> 2532.2245 | Q12: 400 | R12: 40
A13: 1 | B13: 大暑 | C13: 4 | D13: 0 | E13: 800 | F13: =IF(C13>=1,VLOOKUP(R12+MAX(0,R13-R12-C13)+0,药材收益口径!$H$2:$I$222,2,FALSE),0)+IF(C13>=2,VLOOKUP(R12+MAX(0,R13-R12-C13)+1,药材收益口径!$H$2:$I$222,2,FALSE),0)+IF(C13>=3,VLOOKUP(R12+MAX(0,R13-R12-C13)+2,药材收益口径!$H$2:$I$222,2,FALSE),0)+IF(C13>=4,VLOOKUP(R12+MAX(0,R13-R12-C13)+3,药材收益口径!$H$2:$I$222,2,FALSE),0) -> 429.88889 | G13: 460.8 | H13: 5000 | I13: 1000 | J13: =SUM(D13:I13) -> 7690.6889 | K13: =K12+J13 -> 19154.913 | L13: 3276.4 | M13: =M12+L13 -> 32208.4 | N13: =J13-L13 -> 4414.2889 | O13: =K13-M13 -> -13053.487 | P13: =20000+O13 -> 6946.5134 | Q13: 440 | R13: 44 | S13: 023_02 谢飞燕肺气虚（银钱+1000）
A14: 1 | B14: 立秋 | C14: 4 | D14: 0 | E14: 800 | F14: =IF(C14>=1,VLOOKUP(R13+MAX(0,R14-R13-C14)+0,药材收益口径!$H$2:$I$222,2,FALSE),0)+IF(C14>=2,VLOOKUP(R13+MAX(0,R14-R13-C14)+1,药材收益口径!$H$2:$I$222,2,FALSE),0)+IF(C14>=3,VLOOKUP(R13+MAX(0,R14-R13-C14)+2,药材收益口径!$H$2:$I$222,2,FALSE),0)+IF(C14>=4,VLOOKUP(R13+MAX(0,R14-R13-C14)+3,药材收益口径!$H$2:$I$222,2,FALSE),0) -> 419.89474 | G14: 460.8 | H14: 0 | I14: 1000 | J14: =SUM(D14:I14) -> 2680.6947 | K14: =K13+J14 -> 21835.608 | L14: 2650 | M14: =M13+L14 -> 34858.4 | N14: =J14-L14 -> 30.694737 | O14: =K14-M14 -> -13022.792 | P14: =20000+O14 -> 6977.2081 | Q14: 480 | R14: 48 | S14: 024_02 谢飞燕肺阴虚（银钱+1000）
A15: 1 | B15: 处暑 | C15: 4 | D15: 0 | E15: 800 | F15: =IF(C15>=1,VLOOKUP(R14+MAX(0,R15-R14-C15)+0,药材收益口径!$H$2:$I$222,2,FALSE),0)+IF(C15>=2,VLOOKUP(R14+MAX(0,R15-R14-C15)+1,药材收益口径!$H$2:$I$222,2,FALSE),0)+IF(C15>=3,VLOOKUP(R14+MAX(0,R15-R14-C15)+2,药材收益口径!$H$2:$I$222,2,FALSE),0)+IF(C15>=4,VLOOKUP(R14+MAX(0,R15-R14-C15)+3,药材收益口径!$H$2:$I$222,2,FALSE),0) -> 485.31807 | G15: 460.8 | H15: 0 | I15: 0 | J15: =SUM(D15:I15) -> 1746.1181 | K15: =K14+J15 -> 23581.726 | L15: 4776.4 | M15: =M14+L15 -> 39634.8 | N15: =J15-L15 -> -3030.2819 | O15: =K15-M15 -> -16053.074 | P15: =20000+O15 -> 3946.9262 | Q15: 520 | R15: 52
A16: 1 | B16: 白露 | C16: 4 | D16: 0 | E16: 800 | F16: =IF(C16>=1,VLOOKUP(R15+MAX(0,R16-R15-C16)+0,药材收益口径!$H$2:$I$222,2,FALSE),0)+IF(C16>=2,VLOOKUP(R15+MAX(0,R16-R15-C16)+1,药材收益口径!$H$2:$I$222,2,FALSE),0)+IF(C16>=3,VLOOKUP(R15+MAX(0,R16-R15-C16)+2,药材收益口径!$H$2:$I$222,2,FALSE),0)+IF(C16>=4,VLOOKUP(R15+MAX(0,R16-R15-C16)+3,药材收益口径!$H$2:$I$222,2,FALSE),0) -> 473.91395 | G16: 460.8 | H16: 0 | I16: 1000 | J16: =SUM(D16:I16) -> 2734.7139 | K16: =K15+J16 -> 26316.44 | L16: 1550 | M16: =M15+L16 -> 41184.8 | N16: =J16-L16 -> 1184.7139 | O16: =K16-M16 -> -14868.36 | P16: =20000+O16 -> 5131.6401 | Q16: 1560 | R16: 56 | S16: 005_02 治愈世子（银钱+1000，名望+1000）
A17: 1 | B17: 秋分 | C17: 4 | D17: 0 | E17: 2000 | F17: =IF(C17>=1,VLOOKUP(R16+MAX(0,R17-R16-C17)+0,药材收益口径!$H$2:$I$222,2,FALSE),0)+IF(C17>=2,VLOOKUP(R16+MAX(0,R17-R16-C17)+1,药材收益口径!$H$2:$I$222,2,FALSE),0)+IF(C17>=3,VLOOKUP(R16+MAX(0,R17-R16-C17)+2,药材收益口径!$H$2:$I$222,2,FALSE),0)+IF(C17>=4,VLOOKUP(R16+MAX(0,R17-R16-C17)+3,药材收益口径!$H$2:$I$222,2,FALSE),0) -> 468.78571 | G17: 460.8 | H17: 0 | I17: 0 | J17: =SUM(D17:I17) -> 2929.5857 | K17: =K16+J17 -> 29246.026 | L17: 3376.4 | M17: =M16+L17 -> 44561.2 | N17: =J17-L17 -> -446.81429 | O17: =K17-M17 -> -15315.174 | P17: =20000+O17 -> 4684.8259 | Q17: 1600 | R17: 67 | S17: 024_04 王百堂来访（心得+7）
A18: 1 | B18: 寒露 | C18: 4 | D18: 0 | E18: 2000 | F18: =IF(C18>=1,VLOOKUP(R17+MAX(0,R18-R17-C18)+0,药材收益口径!$H$2:$I$222,2,FALSE),0)+IF(C18>=2,VLOOKUP(R17+MAX(0,R18-R17-C18)+1,药材收益口径!$H$2:$I$222,2,FALSE),0)+IF(C18>=3,VLOOKUP(R17+MAX(0,R18-R17-C18)+2,药材收益口径!$H$2:$I$222,2,FALSE),0)+IF(C18>=4,VLOOKUP(R17+MAX(0,R18-R17-C18)+3,药材收益口径!$H$2:$I$222,2,FALSE),0) -> 497.17241 | G18: 460.8 | H18: 0 | I18: 0 | J18: =SUM(D18:I18) -> 2957.9724 | K18: =K17+J18 -> 32203.998 | L18: 1550 | M18: =M17+L18 -> 46111.2 | N18: =J18-L18 -> 1407.9724 | O18: =K18-M18 -> -13907.202 | P18: =20000+O18 -> 6092.7983 | Q18: 1640 | R18: 71
